Workbook

Sheet round1_CuSOD
A1: Name | B1: Group | C1: Activity (5μg/mL) | D1: Expression | E1: Solubility | F1: Purification | G1: expressed sequence | H1: tagged sequence
A2: N39_0.544 | B2: ASR | C2: N | D2: N | E2: N | F2: N | G2: ATGACCATTTACACCACAGACGGCAAACATAAATCCATTGGTCATATCACACTGGAAGACACAGCTTATGGTGTGCTGTTCATTCCAGACCTGCACAATCTGCCACCCGGCCTTCATGGTCTCCATCTTCACGTAAACCCATCTTGCGGCCAACAGGGAATGGCAGCAGGCGGCCACTACGATCCACAGAAAACCGGCAAACATGAGGGACCTTATTCTGACGGTCACCTCGGAGACCTTCCCGTGCTGTACGTCGATGAAAACGGGACTGCGACGACACCGACTTTAGCTCCGCGTCTGAAACTTAATGATTTAAATAATCACGCTCTGATGATCCACGCGGGCGGCGATAATTATTCAGATGATCCCAAGCCGCTCGGTGGTGGCGGTGCGCGGGTAGCCTGTGGAGTGATCGCGGCCGCACTCGAGCACCACCACCACCACCACTGA | H2: MTIYTTDGKHKSIGHITLEDTAYGVLFIPDLHNLPPGLHGLHLHVNPSCGQQGMAAGGHYDPQKTGKHEGPYSDGHLGDLPVLYVDENGTATTPTLAPRLKLNDLNNHALMIHAGGDNYSDDPKPLGGGGARVACGVIAAALEHHHHHH*
A3: N201_0.643 | B3: ASR | C3: N | D3: Y | E3: Y | F3: N | G3: ATGGCCGTGGTTGCCCTCAGTGGAGGGTCAGGCGTGACGGGCAATATCACGTTTATCCAACAGCAGGATGATGGGCCGGTGAGAGTCACCGGGACAATCTCGGGGTTAACTCCAGGGAAACACGGTTTCCACGTACATGAAAAAGGAGACCTGTCAAACGGGTGCGTAAGTGCAGGCGGTCACTTTAACCCGGAAAACAAGAATCATGGCGCCCCTAACGATACTGAACGCCATGTGGGTGATCTGGGAAATATCGAAGCAGATGAAAATGGTGTTGCGACGATAAACATCACAGATAGCGTTATTTCTTTAACAGGTCCACATTCAATTATCGGACGTGCTGTGGTAGTGCATGCGGATGCGGATGATCTGGGTAAAGGCGGAAACGAAGAATCCAAGAAAACCGGCAACGCGGGGGGTCGTGTCGCTTGTGGCGTGATTGCGGCCGCACTCGAGCACCACCACCACCACCACTGA | H3: MAVVALSGGSGVTGNITFIQQQDDGPVRVTGTISGLTPGKHGFHVHEKGDLSNGCVSAGGHFNPENKNHGAPNDTERHVGDLGNIEADENGVATINITDSVISLTGPHSIIGRAVVVHADADDLGKGGNEESKKTGNAGGRVACGVIAAALEHHHHHH*
A4: N5_0.362 | B4: ASR | C4: Y | D4: Y | E4: Y | F4: Y | G4: ATGCGTGCGACTCTGATTGATGCTCAGGGCCAAAAGGTTGGTACCGCAACATTAACACAGACTCCAGAGGGGGTAAAGATAACTGTCGAAGTCAGCAATCTTCCTCCGGGCACCCACGGTTTCCATATCCATGAAAATGGGAAGTGTGAACCACCTGATTTTAAAAGTGCTGGGGGACATTTTAATCCAGCCAATAAACAACACGGGTTAAAGAACCCCGAGGGGCCACACGCAGGCGACTTACCTAACATTGAAGTGAACCCAGACGGAACTGCTAAGGCAGAAGTCGTTGCAAAACGGGTGACCCTCGAAAAGGGCGAACCGAATTCCCTTTTTAAAGAAGGCGGAACCTCATTGGTTATTCATGCCGGGGCGGATGATTACAAAACAGACCCGGCGGGTAACAGTGGAGCACGCATCGCATGCGGGGTGATTGCGGCCGCACTCGAGCACCACCACCACCACCACTGA | H4: MRATLIDAQGQKVGTATLTQTPEGVKITVEVSNLPPGTHGFHIHENGKCEPPDFKSAGGHFNPANKQHGLKNPEGPHAGDLPNIEVNPDGTAKAEVVAKRVTLEKGEPNSLFKEGGTSLVIHAGADDYKTDPAGNSGARIACGVIAAALEHHHHHH*
A5: N63_0.866 | B5: ASR | C5: N | D5: N | E5: N | F5: N | G5: ATGGTTGATATGAAGGATTTAGATAGCGGAAAGGCGATCGGTACTGTTACAATTTCTGAATCAGAATACGGTCTCGTTTTTACCCCGAATCTTAAAGGGCTGCCTCCAGGCATTCACGGTTTCCACATTCATGAGAATGCATCATGTGAGAGCGCGGAAAAAAATGGCAAAACCATACTCGGGGGTGCAGCAGGTGGCCATTATGACCCCGAGAAAACTGGGAAACATGGTTTCCCATGGTCAAATGACAATCACCTGGGTGATCTGCCTGCTCTGTATGTAGATATGGATGGGATGGCGACTCAACCAGTTTTGGCACCCCGAATTACACTTAGTGACTTAAAAGGGCGGGCCCTTATGATTCATGCAGGCGGTGATAACCATAGCGATCATCCTAAGAAGTTGGGTGGCGGCGGAGCGCGTGTTGTATGTGGCGTGATTGCGGCCGCACTCGAGCACCACCACCACCACCACTGA | H5: MVDMKDLDSGKAIGTVTISESEYGLVFTPNLKGLPPGIHGFHIHENASCESAEKNGKTILGGAAGGHYDPEKTGKHGFPWSNDNHLGDLPALYVDMDGMATQPVLAPRITLSDLKGRALMIHAGGDNHSDHPKKLGGGGARVVCGVIAAALEHHHHHH*
A6: N230_0.862 | B6: ASR | C6: N | D6: Y | E6: N | F6: N | G6: ATGGCGGTTCTGCATCCAACGGAAGGGAATAAAGTTACCGGTACTGTTACTTTTACCCAGACGGATGATGGAGTCAAAGTTACGGCAGACGTAACCGGACTCACTCCGGGGAAACATGGGTTTCATATACACGAGTTCGGTGACTGTTCAGCCCCTGATGGGACTAGCGCCGGTGGACATTTCAATCCCACAAACAAACCACACGCCGGCCCGGACGCTGCAGAAAGACATGTAGGGGACTTAGGTAATATCGAAGCCGATGCAGATGGTAATGCCACCCTGGAGTTTGTTGATTCCCGCATTAGCTTGAATGGCGGAAATCATTCAATAATTGGCCGTGCCGTTATTGTACATGCGAAGGCAGATGATTTAAAATCTCAGCCAACCGGAAACGCAGGAGGTCGAATTGCGTGCGGTGTCATCGCGGCCGCACTCGAGCACCACCACCACCACCACTGA | H6: MAVLHPTEGNKVTGTVTFTQTDDGVKVTADVTGLTPGKHGFHIHEFGDCSAPDGTSAGGHFNPTNKPHAGPDAAERHVGDLGNIEADADGNATLEFVDSRISLNGGNHSIIGRAVIVHAKADDLKSQPTGNAGGRIACGVIAAALEHHHHHH*
A7: N64_0.834 | B7: ASR | C7: Y | D7: Y | E7: Y | F7: Y | G7: ATGGTTGATATGAAAGACCTGAAAACAGGTAAATCCATCGGAACAGTTACAATATCTGAATCCGAATACGGGCTGGTGTTTACACCGAATCTGAAAGGCTTACCCCCAGGAATACACGGCTTTCACGTACACGAGAATGCTTCATGTGAACCCGCAGAAAAAGATGGCAAAATGGTTCTGGGTGGAGCTGCAGGAGGCCATTATGATCCGGAGAACACGGGCAAACATGGGTTCCCGTGGAGCAATGACAATCATCGCGGAGATCTCCCGGCCCTGTATGTAGATAAAGATGGCATGGCAACCCATCCTGTTCTGGCACCGAGATTGACATTAGATGACTTAAAAGGCCGCGCCTTAATGATTCATGCAAACGGTGATAACTATTCGGATCACCCGAAGCCTTTAGGAGGAGGGGGCGCGCGAGTGGCTTGCGGGGTAATTGCGGCCGCACTCGAGCACCACCACCACCACCACTGA | H7: MVDMKDLKTGKSIGTVTISESEYGLVFTPNLKGLPPGIHGFHVHENASCEPAEKDGKMVLGGAAGGHYDPENTGKHGFPWSNDNHRGDLPALYVDKDGMATHPVLAPRLTLDDLKGRALMIHANGDNYSDHPKPLGGGGARVACGVIAAALEHHHHHH*
A8: N316_0.952 | B8: ASR | C8: N | D8: Y | E8: N | F8: N | G8: ATGACGGCTGAGATTATGGGTGCAGAGGGAAAAACACTGGGTACCGTTACAGTTACTGCTACTCCCTCCGGAATTGTCCTGGTTACGTTAGCCCTCACGGGCTTGCCTCCAGGCATCCATGCTGTGCACCTGCATCAGACTGGTGCATGTGAAGCGCCAGATTTTGAGAGTGCCGGAGGACATTTAGCTGGTGACGGCGAACATGGAGTTCTTGCGGAAAATGGGCCCCACCCGGGCGATATGCCAAATATCCACGTACCAGAAGGGGGTGCCTTGACCGTCGAATATTTCATACCTGGACTGACACCGGAAATGGTAGCCGACGAAGACGGGAGTGCCATAATTATTCATGCGCAGGCCGATGACTACCGCGGTCAACCCTCTGGTCATGCGGGTGGTCGCATTGCTTGCGGCGTGTTTGCGGCCGCACTCGAGCACCACCACCACCACCACTGA | H8: MTAEIMGAEGKTLGTVTVTATPSGIVLVTLALTGLPPGIHAVHLHQTGACEAPDFESAGGHLAGDGEHGVLAENGPHPGDMPNIHVPEGGALTVEYFIPGLTPEMVADEDGSAIIIHAQADDYRGQPSGHAGGRIACGVFAAALEHHHHHH*
A9: N34_0.772 | B9: ASR | C9: Y | D9: Y | E9: Y | F9: Y | G9: ATGAATGCTGTTACCGCGGACGGGGTAGGTAAATCAATTGGAACAGTTACCATTGAAGAAACGCCTTATGGCCTGCTTTTCACCCCGGATCTTAAAGGCCTCCCTCCGGGCTTACACGGTTTTCACGTCCATGAGAACCCATCTTGTGAGCCAGCTGAGAAAGACGGCAAAACCGTGGCGGCATTGGCGGCGGGAGGTCACTATGATCCAGAAAATACCGGCAAACACGAAGGGCCTTACGGCGATGGTCATTTGGGGGACTTGCCCGCATTATACGTGGACGCGGATGGTACAGCAACTACTCCGGTTCTTGCACCGCGCTTAAAACTTGATGATATTAAAGGACATGCCCTCATGATCCATGCAGGCGGTGATAATTACTCGGACCATCCGAAGCCCTTAGGCGGAGGAGGAGCGCGCATTGCGTGCGGTGTTATTGCGGCCGCACTCGAGCACCACCACCACCACCACTGA | H9: MNAVTADGVGKSIGTVTIEETPYGLLFTPDLKGLPPGLHGFHVHENPSCEPAEKDGKTVAALAAGGHYDPENTGKHEGPYGDGHLGDLPALYVDADGTATTPVLAPRLKLDDIKGHALMIHAGGDNYSDHPKPLGGGGARIACGVIAAALEHHHHHH*
A10: N311_0.882 | B10: ASR | C10: N | D10: Y | E10: Y | F10: Y | G10: ATGACAGCCGAACTCAAAGACGCGGACGGTAAAGCGGTGGGAACAGTTACGCTGACCGAAACGCCGTCAGGTGTGCTGATAACCGCTGATCTCACTGGGCTGCCACCAGGTGAACATGGGTTTCATATCCATGAAACCGGCGCCTGCGAACCAGACTTTAAGAGCGCTGGGGGACATTTCAATCCGGCTGGTGACGAACACGGTCTGATGGCGGAAGGAGGCCCGCACGCGGGTGATATGCCGAACATTCATGTGCCCGAAGACGGTAAACTGCGTGTCGAGGTCTTTAATCCTGGTGTCACTTTAGCGAGTGGAGAACCGAATGACCTGTTTGATGAGGATGGCTCAGCGATCGTTATTCATGCGGGCGCAGACGACTACCGTAGCCAGCCATCTGGTGATGCGGGAGATCGCATTGCATGTGGCGTTATTGCGGCCGCACTCGAGCACCACCACCACCACCACTGA | H10: MTAELKDADGKAVGTVTLTETPSGVLITADLTGLPPGEHGFHIHETGACEPDFKSAGGHFNPAGDEHGLMAEGGPHAGDMPNIHVPEDGKLRVEVFNPGVTLASGEPNDLFDEDGSAIVIHAGADDYRSQPSGDAGDRIACGVIAAALEHHHHHH*
A11: N97_0.752 | B11: ASR | C11: N | D11: Y | E11: N | F11: N | G11: ATGCATGCTATTGATGCGGAGGGCGTAGGAAAAGCTATCGGTACGGTTACCATTCGGGACACACCGGATGGTTTAGTGTTCACCCCGGATCTGTCAGGGTTACCGGCCGGGGCACACGGCTTTCATCTCCACGAAAATGGGAGCTGCGGCCCAGGCGAAAAAGATGGAAAAACTGTGGCAGGCCTGGCTGCCGGGGGTCACTACGACCCAGAAAATACGGGAAAGCATTTGGGACCTTATGGCGTGGGCCACAGAGGGGATCTGCCTGTACTGGTAGTCGCGGCTGATGGAACAGCGACCACTCCTGTAGTTGCGCCACGCTTAAAAGTATCCGATGTCAAGGGCCGTGCATTAATTATACACGCGGGCGGTGATAATTATTCACAAGAACAGCCCCTTGGCGGCGGTGGGGCGCGCATTGCCTGCGGAGTGATCGCGGCCGCACTCGAGCACCACCACCACCACCACTGA | H11: MHAIDAEGVGKAIGTVTIRDTPDGLVFTPDLSGLPAGAHGFHLHENGSCGPGEKDGKTVAGLAAGGHYDPENTGKHLGPYGVGHRGDLPVLVVAADGTATTPVVAPRLKVSDVKGRALIIHAGGDNYSQEQPLGGGGARIACGVIAAALEHHHHHH*
A12: N353_0.977 | B12: ASR | C12: N | D12: N | E12: N | F12: N | G12: ATGACGGCGTCTCTTAAGACTGCAGATGGTAAAGCAGCTGGCACAGCAACCGCGACTGAGACGGATGGGGGTGTTCGGGTGGCAGTAAATGCGACAGGACTGCCGCCCGGGGAACACGGTGTTCATGTGCATATGACCGGGAAATGTGATGCTCCTAAATTTGAAACGGCAGGTGGCCATTGGAATCCTACTGGCGCGCAACATGGGTTGATGAATCCGCAAGGCCCGCATGCCGGTGACATGCCCAACTTAACCGTGGGGGCTGATGGTCGCGGCACACTCGCCTATACCATCAAAGGCGCTACACTCGCGGGCTTACTGGATGCCGACGGAGCGGCTCTTGTGGTCCATGCATCGGCAGATGACCAAAAGACCGATCCGAGCGGTAATTCCGGTGATCGGATTGCTTGCGGAGTTTTTGCGGCCGCACTCGAGCACCACCACCACCACCACTGA | H12: MTASLKTADGKAAGTATATETDGGVRVAVNATGLPPGEHGVHVHMTGKCDAPKFETAGGHWNPTGAQHGLMNPQGPHAGDMPNLTVGADGRGTLAYTIKGATLAGLLDADGAALVVHASADDQKTDPSGNSGDRIACGVFAAALEHHHHHH*
... A19: N382_0.622 | B19: ASR | C19: Y | D19: Y | E19: Y | F19: Y | G19: ATGAACGTGAGCCTGATTAACGCCGAAGGGGAAAAGATTGGTACTGCAATGCTGACCCAGACATCCGAAGGTGTGAAGATAACACTGGAGGCTGAAAACCTGCCGCCAGGAACGCACGGTTTCCATATACACGAAAACGGCAAATGCGAGCCTCCAGATTTTAAGTCTGCGGGAGGACATTTTAACCCGACTAATAAACAGCATGGCTTCGAAAATCCTAAAGGTCCACATGCAGGTGATCTGCCTAATATAGAAGTTAACCCTGACGGAACAGTAAAAGCCGAGTTCGTTGCAAAACAGGTTACCCTGGAAAAAGGTAAGCCGAACTCTCTGCTCAAAGAAGGCGGCACCTCACTGGTCATTCATGAGAAAGCGGACGATTACAAAACTGATCCAGCAGGCAACTCTGGCGCACGAATTGCATGTGGGGTGATCGCGGCCGCACTCGAGCACCACCACCACCACCACTGA | H19: MNVSLINAEGEKIGTAMLTQTSEGVKITLEAENLPPGTHGFHIHENGKCEPPDFKSAGGHFNPTNKQHGFENPKGPHAGDLPNIEVNPDGTVKAEFVAKQVTLEKGKPNSLLKEGGTSLVIHEKADDYKTDPAGNSGARIACGVIAAALEHHHHHH*
A20: 1201 | B20: ESM-MSA | C20: N | D20: Y | E20: N | F20: N | G20: ATGGTACAAATATATAATCAGTCTGGAGACAAAGTTGGTACAGCGAAATTTGCCCAGGAGGCAAAAGGTGTAAAAGTTAGCATTAAAGCAGAGGGATTTACGCCGGGCACCCACGGCGTTCATGTTCATGAAACGGGTCAGTGTAAAGCACCAGACTTTAGTAGTTCCGGAAAACATCTTAACCCCAATAATAAAAAGCATGGCATCTTGAATCCTGAAGGACCGCATAACGGCGACTTACCCAATATTGTAGCTGACAAGAGTGGTATGATTAAAATGAATATGGTGGCCCCGAAAGTGGCTCTGAAGGAAGGAAAGGACATGACCCTGCTGCGGAAAGACGGTGCTTCATTAATAATCACCGAGAAGCAAGATGATGGTATGGTTCAGCCCGCCGGCAATAGTGGTAAACGAATGGCCTGTGGTGTTATTGTGAAAGAAGCCTCGGAAACTAAAAAAGAAGCGGCCGCACTCGAGCACCACCACCACCACCACTGA | H20: MVQIYNQSGDKVGTAKFAQEAKGVKVSIKAEGFTPGTHGVHVHETGQCKAPDFSSSGKHLNPNNKKHGILNPEGPHNGDLPNIVADKSGMIKMNMVAPKVALKEGKDMTLLRKDGASLIITEKQDDGMVQPAGNSGKRMACGVIVKEASETKKEAAALEHHHHHH*
A21: 4798 | B21: ESM-MSA | C21: N | D21: Y | E21: Y | F21: N | G21: ATGACAGTTGAAATTCTGAATACAAAAGGGGATTCCGTGGGTACCGCAGAGATCGAACCCGAGTCAGACGGTGTGGGCGTAGTGTTGAATCTTGAAAACCTGGAGTCTGGTGAACACGGACTGAAATTTCACGATGCCGGTAAGTATGAAACTCCGGGGTTCAATAGCGCCGGAGAGCCGTTCGCTCAGGAGATGCAAACTATTGAAATCGGAGAAGACGGAGTTGCGAAAGATGAATTTATAGTCCAAAACGTTACTCTGAAAAAGGATGCCGAGAACAGTCTGCTGAAAGACGACGGCACAGCACTGATTGTCTATTCTGGCGAAGATGCAGGCGAGTGCATTGCCTGCGGTGTGGTGGCGGCCGCACTCGAGCACCACCACCACCACCACTGA | H21: MTVEILNTKGDSVGTAEIEPESDGVGVVLNLENLESGEHGLKFHDAGKYETPGFNSAGEPFAQEMQTIEIGEDGVAKDEFIVQNVTLKKDAENSLLKDDGTALIVYSGEDAGECIACGVVAAALEHHHHHH*
A22: 1432 | B22: ESM-MSA | C22: N | D22: Y | E22: N | F22: N | G22: ATGACGGCCAATCTGAAAGATGCACAGAATCGATTGATTGGCGTGGCCACCTTTTCGGAGCTCGAGAATCGCTTAGTAAGAATTCACGTTTCAGCGAAGGGATTACCGCCGGGTCGTCACGGCATACATATACATGAAGTTGGCAATTGCACAGCTCCAACGTTCGTAAGTGCAGGAGGCCACTATAATCCACTGGGCCGTGAGCACGGCATCGAAAATCCGAAAGGACCGCATGCCGGCGATCTGCCAAATCTGATTGTAGAAGAGGATGGGACAGCAGCCTTAGATGTGGTTACTAATCTGGCGACATTAAGTTCTACAGCAGATTCTTTATTTCAGGCAAATGGAACGAGTTTGGTGATTCATGCCCTGCCAGATGATCAGAAGTCAAACCCATCCGGAAATAGCGGAGATCGCATTGCCTGCGGTGTTATTGCGGCCGCACTCGAGCACCACCACCACCACCACTGA | H22: MTANLKDAQNRLIGVATFSELENRLVRIHVSAKGLPPGRHGIHIHEVGNCTAPTFVSAGGHYNPLGREHGIENPKGPHAGDLPNLIVEEDGTAALDVVTNLATLSSTADSLFQANGTSLVIHALPDDQKSNPSGNSGDRIACGVIAAALEHHHHHH*
A23: 4803 | B23: ESM-MSA | C23: N | D23: N | E23: N | F23: N | G23: ATGCAGATCAACCCCGTAAACGGGGATAAAGACGTGGGTCGGGTTGAAGTGAAGGAGAGCGCCTACGGTTTACTTTTCACGCCGAAACTGACTAACCTGCCGCACGGTCTGCACGGGTTCCACATCCATGAAAAACCGAGTTGTGAACCAGCCGAGAAAAATGGGAAAGTTGTAGCCGCGCTCGGCAGTGGTGATCATTGGGATCCAAAACACACCAAGCAGCATGGTTATCCTTGGGGCGACGATTCCCATATGGGTGACCTGCCGGCTCTGTTTGTAAATCAGGATGGGAGCGCCCAGACGCCTGTGCTGGCACCCCGTCTGCCAGACTTGGCTGACGTCAAAGGCCGAAGCTTGATGTTACACGCAGGAGGTGATAACTATTCTGATCACCCTGATCCACTGGGGGGAGGTGGAGGTAGACTGGCCTGCGCCGTCATGGCGGCCGCACTCGAGCACCACCACCACCACCACTGA | H23: MQINPVNGDKDVGRVEVKESAYGLLFTPKLTNLPHGLHGFHIHEKPSCEPAEKNGKVVAALGSGDHWDPKHTKQHGYPWGDDSHMGDLPALFVNQDGSAQTPVLAPRLPDLADVKGRSLMLHAGGDNYSDHPDPLGGGGGRLACAVMAAALEHHHHHH*
A24: 1949 | B24: ESM-MSA | C24: N | D24: Y | E24: N | F24: N | G24: ATGCGAATTAAAATGGGGCCGTTATATCCGGAATTGAATGGAGTTGCATATTTTATTAGCGAACCAGGCGGTACAAGAGTAAGCGTCGAAGTTACCGGTTTGCCGCCTTATGATCCTGATACCGATGAGCAGTACCCTATTGGCCCCCATGGTCTTCACGTGCACAAATTCGGTACCTGTAAAGTAGGAGACCCGAATGACCCTTTCGAGGCGGCTGGGGGACACTACGCACCAGATGCTGAGCATGGCCCGCATCATGCCGGTGATATCCCCGTTCTTTTCAGTAATAATGGCCAGGCTCGTATGACTGTTTTCACTGCTGATTATGCCGTGGATGACGTTGTTGGCCGCGCAGTAGTGATTCACGACGTGCCGGATGATTATGAGAGTCAACCTGCGGGCGATGCGGGCCATCGCTTAGCATGTGGCGTCATTGCGGCCGCACTCGAGCACCACCACCACCACCACTGA | H24: MRIKMGPLYPELNGVAYFISEPGGTRVSVEVTGLPPYDPDTDEQYPIGPHGLHVHKFGTCKVGDPNDPFEAAGGHYAPDAEHGPHHAGDIPVLFSNNGQARMTVFTADYAVDDVVGRAVVIHDVPDDYESQPAGDAGHRLACGVIAAALEHHHHHH*
A25: 2417 | B25: ESM-MSA | C25: N | D25: N | E25: N | F25: N | G25: ATGCAACTTAACCCTGCTAATGGCGCCAAAGCAGTTGGCACCGTATCCGTCAGTGAAAGCAAATACGGACTGGTTTTCACACCTAATTTAGCAGGATTAAGCCCCGGCATTCATGGATTTCATATTCATGAAAACGCCAGCTGTGCGCCTAGAGAAAAGGATGGGAAGGTCACAGAGGCGCTGGGCGCAGGAGGCCACTGGGACCCAAAGGAAACCAAAAAACACGGGTACCCGTGGCAGCAGGGGGCGCATATTGGAGATCTGCCCGCCCTGAACGTGAATCACGATGGTACGGCTAAATACCCTGTTCTGGCGCCTCGGCTGAAGAAGCTCTCGCAGATTAAAGGTCGTTCATTAATGGTACACGCAACCGGTGATAACCATTCTGATCATCCGGAACCACTGGGGGGCGGAAAAGGTCGCATGGCGTGTGGCGTGATTGCGGCCGCACTCGAGCACCACCACCACCACCACTGA | H25: MQLNPANGAKAVGTVSVSESKYGLVFTPNLAGLSPGIHGFHIHENASCAPREKDGKVTEALGAGGHWDPKETKKHGYPWQQGAHIGDLPALNVNHDGTAKYPVLAPRLKKLSQIKGRSLMVHATGDNHSDHPEPLGGGKGRMACGVIAAALEHHHHHH*
A26: 187 | B26: ESM-MSA | C26: N | D26: N | E26: N | F26: N | G26: ATGGCTGTGTGTGTGGTACGTGGCGACTCTTCCGTCAAGGGCGTTGTCGTATTCGAGCAGGCCAGTGAGAACTCCCCAACTCGTATTACGTATGAAATAACCGGCAACGACCCAAATGGGGTACGCGGTTTTCATGTCCACGAGTTTGGAGATAATACCTCAGGTTGCACGTCTGCGGGTCCTCATTTTAACCCATTTGGAAAAGGCCACGGCGCTCCACGAGATAAAGATCGCCATGTCGGTGACATGGGCAATATTACCACCGATGCCAACGGTAATGCCCAAGGTACCATGGAGGACAGCAATGTTTCACTGTTTGGGCCGGACACCATTATAGGTCGTACAGTAGTTGTGCACGCCGGTACCGATGACCTGGGAAAGGGTAACATCGAGGAAAGTCTGAAGACCGGCCACGCCGGCCCTCGCCCCGCCTGCGGGGTGATCCTGCTGTTAATTTTTCTGAAGATAAAATTTGCGGCCGCACTCGAGCACCACCACCACCACCACTGA | H26: MAVCVVRGDSSVKGVVVFEQASENSPTRITYEITGNDPNGVRGFHVHEFGDNTSGCTSAGPHFNPFGKGHGAPRDKDRHVGDMGNITTDANGNAQGTMEDSNVSLFGPDTIIGRTVVVHAGTDDLGKGNIEESLKTGHAGPRPACGVILLLIFLKIKFAAALEHHHHHH*
A27: 2931 | B27: ESM-MSA | C27: N | D27: Y | E27: Y | F27: Y | G27: ATGAAACTGGTGACGGATCAGGGTATCGGCAAAAGTATAGGCGAAATTACCGTGGCGGAAACCCCGTATGGCCTTTTATTTACCCCAGACGTCCACGGTCTTGCACCGGGGATTCATGGCTTCCACTTACATACTATCGCATCATGTGCAGCGGGCGTAAAAGATGGTAAACCTGTCCCGGCTCTGGCCGCTGGTGGGCATTTAGATCCTGAAAACACGCTGAAACACTTAGGTCCATATGACGATAAGGGCCATCTGGGCGATTTACCGGGTTTGTACGTCGGCTCTGATGGCAATGCCACAGCGCCCCTTCTCGCGCCCCGAGTTAAGGCTTTAATGGACCTGAAAGGGCATAGTTTAATGATCCATAAGGGTGGCGATAATTATGCCGACCAGCCTGCTCCGCTGGGTGGTGGCGGTGCTCGCTTTGCTTGTGGTGTCATTGCGGCCGCACTCGAGCACCACCACCACCACCACTGA | H27: MKLVTDQGIGKSIGEITVAETPYGLLFTPDVHGLAPGIHGFHLHTIASCAAGVKDGKPVPALAAGGHLDPENTLKHLGPYDDKGHLGDLPGLYVGSDGNATAPLLAPRVKALMDLKGHSLMIHKGGDNYADQPAPLGGGGARFACGVIAAALEHHHHHH*
A28: 1505 | B28: ESM-MSA | C28: N | D28: Y | E28: N | F28: N | G28: ATGACCATTGAAGGTGGTCCGTTGGCCCCAGGTCTCAAGGGAGTCGTGTACTTTCGCGAAGTGAAGGGTGGTACGGAGGTCCGTGTTGAAGTGATAGGCTTGCCCCGCTATAAACCGGCGGCAAATGATGCACAGCCAGTCGGCCCGCACGGCTTCCACATCCACGTAAATGGTAGTTGCAAAACCGGCGACCCGAGTAATCCTTTCGAAAGCGCCGGCGATCACTGGAACCCTACCAACCAACCTCATGGGAACCATGCCGGTGACTTTCCAGTTCTGTTCTCTAATAACGGATATGCAAGAATGAGCTTTTTCACAAATAAATTCAAGGTTCAGGACGTGGTGGACCGTGCCGTGATGATTCATGAATCTCCCGATGATTATAGATCTCAGCCGTCGGGCAAAGCCGGTAAACGGCTGGCATGTGGGGTAATAGCGGCCGCACTCGAGCACCACCACCACCACCACTGA | H28: MTIEGGPLAPGLKGVVYFREVKGGTEVRVEVIGLPRYKPAANDAQPVGPHGFHIHVNGSCKTGDPSNPFESAGDHWNPTNQPHGNHAGDFPVLFSNNGYARMSFFTNKFKVQDVVDRAVMIHESPDDYRSQPSGKAGKRLACGVIAAALEHHHHHH*
A29: 196 | B29: ESM-MSA | C29: N | D29: Y | E29: N | F29: N | G29: ATGGTCGATATGAAGAACATGCAAACGGGCGAAAAGATCGGAACTGTTGTGATCAGCCAGCACCAGTACGGTACTATTTTCACTCCGAACTTGTTTTCTCTCCCAGCGGGCGCTCATGGCTTCCATCTTCATCATAAAGCAAGTTGTGAAGCAGCGCAAAAAGATGGTGCCATGGTCCCGGCAGGCTCGGCAGGTGGTCACTATGATCCGAAAAAGACGGGCAAACACGCGGAGCCGTGGGATTTTCACGGTCATGCTGGTGACTTACCAGTGCTGTATGTCGATAAAAACGGTATGGCGAGCCAGCCAGTGTTGGCGCCGCGTCTCACATTAAAAGAGGTTAAAGGCCGTAGCCTTATGATCCATGCCGGAGGAGACAACTATTCTGACGATCCGAAAAAGCTGGGAGGCGGAGGGGGTCGTTTAGCGTGTGGTGTCATCGCGGCCGCACTCGAGCACCACCACCACCACCACTGA | H29: MVDMKNMQTGEKIGTVVISQHQYGTIFTPNLFSLPAGAHGFHLHHKASCEAAQKDGAMVPAGSAGGHYDPKKTGKHAEPWDFHGHAGDLPVLYVDKNGMASQPVLAPRLTLKEVKGRSLMIHAGGDNYSDDPKKLGGGGGRLACGVIAAALEHHHHHH*
A30: 3209 | B30: ESM-MSA | C30: N | D30: N | E30: N | F30: N | G30: ATGGCTGTCATCGATGCCGATAGCACTTCAAATGCCAACGGCACCGTAACCTTCACTGAAGAAGGCTCTACAGTAAAAATGGAAGCCCTTCTCTCAGGCCTGACTCCGGGCAAACATGCAATCCACATACATGAAAATGCTGACTGTTCCGCTGCCGACGGTACGTCAAGTGGCGGCCATTGGAATCCAACCAACGACCCGCATGGGAAATGGGGCGCCGAGTCTGGCTATCATAAAGGTGATATTGGCAATTTTTCAGCAGATGACAATGGTAAAGGTACAGTGACCATTACAACAAATGAATGGTGTATTGGTTGTGGGGATGCCGATAAAGACATTGGTGGTAAAGCACTGATCGTCCATCAGGGGACCGATGACTTTACGACCCAACCCACAGGCGATGCTGGGGCCCGTATTGCGTGTGGATCGATCGCGGCCGCACTCGAGCACCACCACCACCACCACTGA | H30: MAVIDADSTSNANGTVTFTEEGSTVKMEALLSGLTPGKHAIHIHENADCSAADGTSSGGHWNPTNDPHGKWGAESGYHKGDIGNFSADDNGKGTVTITTNEWCIGCGDADKDIGGKALIVHQGTDDFTTQPTGDAGARIACGSIAAALEHHHHHH*
A31: 2773 | B31: ESM-MSA | C31: N | D31: N | E31: N | F31: N | G31: ATGGAGATCCAAGGTGGGCCTCTGGCTCCTGATGTGAAGGGTGTCGTGATATTTGTTGACGTTGTAAATGGAACCGAGGTAGTCGTTGACGTCCAAAACCTGCCACCGTTCCAGCCGGCGCGAAATAATAAAGATGCGATTGGTCCACATGGGTTTCATATTCATGAGAATGGAAATTGTGCCGTCGGAGATCCCGATAACCCTTTTACGGCGGCTGGAGAACACTGGAATCCTACCGACCAGCCCCATGGGAACCATGCAGGGGATTTCCCCGTAATTTTTAGTAATAAAGGATTTGCGCGCATGATATTTTACACAAATAAATTCACGGTGAATCAAATTGTCGGGAAGGCTGTGATTATACATGAGAATCCCGATGATTATCGTACTCAACCGGCCGGTGGTGCCGGGAAGCGCCTGGCGTGTGGTATTATCAACCCTGTACTGCGTGCAACATATAAATGGGCGGCCGCACTCGAGCACCACCACCACCACCACTGA | H31: MEIQGGPLAPDVKGVVIFVDVVNGTEVVVDVQNLPPFQPARNNKDAIGPHGFHIHENGNCAVGDPDNPFTAAGEHWNPTDQPHGNHAGDFPVIFSNKGFARMIFYTNKFTVNQIVGKAVIIHENPDDYRTQPAGGAGKRLACGIINPVLRATYKWAAALEHHHHHH*
... A55: 2480 | B55: GAN | C55: N | D55: Y | E55: Y | F55: N | G55: ATGGTAGAAATGTACAATCCCAATGGAGACTCCCTGGGCTATGTTAAATTGTCAGAACAGTGGGAAGGTGTGATGCTCAAACTGAATGCCAAAGGCCTGCCACCTGGAGAGCATGCGATTCATATTCATGAGCAGGGCAAGTGCGAGCCCCCGGATTTTAAGTCCGCAGGCAACCATTTTAATCCGGAAGATAAAGAACACGGTTTACTGCATCCTAAGGGAAGCCATGCTGGGGATCTGCCTAACTTGATCGTAGAACGCGATGGCAAGGTTAAGGCAGAGTTAATGGCCCCGGATGTTACAATCAAAGAAGATACCAAAAATATTGTGACCAAAGAAGGAACTTCTATTGTCATTACGGAAGGCCCGGATGATGGGATGACACAGCCAGCGGGCGATTCAGGGGCACGGATCGCTTGTGGTGAAATTGTACAGGAAAAGGAGAATGGTAAGAATAAGGCGGCCGCACTCGAGCACCACCACCACCACCACTGA | H55: MVEMYNPNGDSLGYVKLSEQWEGVMLKLNAKGLPPGEHAIHIHEQGKCEPPDFKSAGNHFNPEDKEHGLLHPKGSHAGDLPNLIVERDGKVKAELMAPDVTIKEDTKNIVTKEGTSIVITEGPDDGMTQPAGDSGARIACGEIVQEKENGKNKAAALEHHHHHH*
A56: A0A7X3SKS3 | B56: TEST | C56: N | D56: Y | E56: N | F56: N | G56: ATGGTTATCAAAGGTTCTAAAAAGTACCCTGATATTAAGGGTCGCGCTGCATTTTATGATACGTATGGAGGAACCGTAGTAGTTGCTACCGTTTACGGCCTGCCTCAGAAGCGCGGCGAAAACAACGGAGGATTCCATGGGTTTCATATACATGAAGGGGGGACGTGTTCAGGCAATGTACAGAATGAATTTGCCGATGCGAAAGGTCATTACAACCCCGGCGTCTTTCCACATCCGGAGCATGATGGAGATCTGCCACCTCTTCTGTCGAATAACGGTACAGCTTGGATGGCGGTATATACCTCCAGATTCTATCCAGAAGATGTGATTGGAAGAACTGTCATAATTCACGAAAATGCGGATGACTTTCACTCCCAGCCTTCAGGAGACGCAGGTGAGATGATTGCATGTGGTGAAATAGTTTCCTGGTCACCGGATTTTTGCCGACGTGCGGCCGCACTCGAGCACCACCACCACCACCACTGA | H56: MVIKGSKKYPDIKGRAAFYDTYGGTVVVATVYGLPQKRGENNGGFHGFHIHEGGTCSGNVQNEFADAKGHYNPGVFPHPEHDGDLPPLLSNNGTAWMAVYTSRFYPEDVIGRTVIIHENADDFHSQPSGDAGEMIACGEIVSWSPDFCRRAAALEHHHHHH*
A57: A0A3B0SJ13 | B57: TEST | C57: N | D57: N | E57: N | F57: N | G57: ATGGCCGGCCAATTTATTGGCGTAGACGGAGCACCCATGGGCTATGTGGTACTGACAAATGCCCCCAATGCAGGGGTTGTAATGCGCGTAGATTTAGCGGGAGTTTCTGAAGGATGGCACGCATTACACCTTCATAAAGTTGGTGATTGCAGTGACTATGCAGACGGTTTCAAAGCTTCCGGGTCACATGTGGATCCAGACGATCAACCACACGGACTCCTGAATATTTATGGCCCCGAGCGCGCGGACATGCCGAATATTTATGCGGGTGCGGACGGACATGCAACGGCAGAATTATTCAACGGTACCGTTGCGCTGTTTGCCTCTGAGGCTAGTGCAGCTCAGGCCGGCGCGGCCGCACTCGAGCACCACCACCACCACCACTGA | H57: MAGQFIGVDGAPMGYVVLTNAPNAGVVMRVDLAGVSEGWHALHLHKVGDCSDYADGFKASGSHVDPDDQPHGLLNIYGPERADMPNIYAGADGHATAELFNGTVALFASEASAAQAGAAALEHHHHHH*
A58: A0A0F2NFV0 | B58: TEST | C58: N | D58: Y | E58: Y | F58: Y | G58: ATGCAGGATAAAGCCGGTGCTGAAGCGACCTTGCAGGGGACAGACGGGCGTGAGCACGGTACCGTAAACTTTACGGAAGGCCCTCATGGACTGTTACTGAAAGCCGATCTTAAAGATTTGCCGCCAGGGACGCATGCATTCCATCTTCACGCTACAGGTGTTTGCTCTCCCGATTTTAAGGCTGCTGGAGGACATTATAACCCGACCGGGAAAAAACATGGTTTTATGAGTGCTGACGGTCCGCACGCGGGTGACATGCCTAATATACATGTTCCTGAGAGCGGGAAACTGCAGTTTGAACTGTTTCTGCCTGATATTACAGTTTCAGAAGGCTCTGCTGCCTTATTAGATGCCGATGGTACGGCAGTTCTCCTTCATAAGGATCCGGACGACTATAAAACGGATCCGGCTGGGGCTGCAGGTGATCGAATTGCTTGCGGCGTTGTTAAGGCCAAAGCGGCCGCACTCGAGCACCACCACCACCACCACTGA | H58: MQDKAGAEATLQGTDGREHGTVNFTEGPHGLLLKADLKDLPPGTHAFHLHATGVCSPDFKAAGGHYNPTGKKHGFMSADGPHAGDMPNIHVPESGKLQFELFLPDITVSEGSAALLDADGTAVLLHKDPDDYKTDPAGAAGDRIACGVVKAKAAALEHHHHHH*
A59: A0A210PQ25 | B59: TEST | C59: N | D59: N | E59: N | F59: N | G59: ATGACGTGTCGTTTTAATTCCTCAGATACTAACATTGCCGGCAGAGCAGATCTTAGACAGTTCGTGTTTGGTGATTTCCCAGTTGATATCCGCATTCAGGTGTGGGGACTGCCGCGTTCGCCGGTTGACACTCAGCGGGGAATACATATCCACGAATTTGGCGATGTGGGTGCGAAGTGTAGTCGCGTGGGTCCTCATTTAAATCCCGCCCAGACTCGCCATGGCGGTCGTAATACTTTTGCGTTCCTCCGTCATGTTGGTGACCTGGGTAATATGCTGCAGAGCCCGCAGGGGGTTACATCCACGCAGTTCCGCGATGGGGTAATTTCTTTACAAGGGCCGACCTCAGTGATCGGTCGGAGCTTGGTCATCAAATATGAACGAGATGATGAAGGCTTTGGTACCAACGTTGATTCACTTCAAAACGGCAATGCCCGTACACCTCTGGCGTGCTGCACTTTAGCTCGCTCAGGCCCGGCAAACTGGAATGATGCGGCCGCACTCGAGCACCACCACCACCACCACTGA | H59: MTCRFNSSDTNIAGRADLRQFVFGDFPVDIRIQVWGLPRSPVDTQRGIHIHEFGDVGAKCSRVGPHLNPAQTRHGGRNTFAFLRHVGDLGNMLQSPQGVTSTQFRDGVISLQGPTSVIGRSLVIKYERDDEGFGTNVDSLQNGNARTPLACCTLARSGPANWNDAAALEHHHHHH*
A60: A0A067TI43 | B60: TEST | C60: N | D60: N | E60: N | F60: N | G60: ATGCAGAGTACATCGGCCGTTGTTGTCTTACGGGGAGACTCCTCAGTTACTGGCACAGTCACCTTTCGGCAACGTTCCAAAGGTCCTGTAACCATCTCTGGGAAAATCCAGGGCCTGAGTCCAAACGCCCTTCGGGGGTTTCACGTCCACCAGCTGGGTGATTTATCCGGCGGCTGTCTGTCTGCGGGTTCTCACTTTAACCCTTACGGCAAGACCCATGGTCCGCCGACTGCTAGCACACGTCATGTCGGTGATCTTGGCAATATCAAAACGGACGAGAACGGGGAAGCCAATTTTGAATTCACCGATCATCTCATTTCTCTGCAAGGGCCCAATTCCATCATCGGAAGATCTGTGGTGGTTCACGCAGGGACAGATGATTTAGGGGCGGGTGGGGATGACGAGAGTCTGAAGACCGGTAACGCAGGTGCTCGTGCGGCGTGTGGGGTGATAGGGCTTGCCGCGGCCGCACTCGAGCACCACCACCACCACCACTGA | H60: MQSTSAVVVLRGDSSVTGTVTFRQRSKGPVTISGKIQGLSPNALRGFHVHQLGDLSGGCLSAGSHFNPYGKTHGPPTASTRHVGDLGNIKTDENGEANFEFTDHLISLQGPNSIIGRSVVVHAGTDDLGAGGDDESLKTGNAGARAACGVIGLAAAALEHHHHHH*
A61: A0A317MZG1 | B61: TEST | C61: N | D61: N | E61: N | F61: N | G61: ATGGCACTGGACGCTTCTGGCGCATCGGCACCTATCGGTAGCATCTCTGCATCATCATCCCCTTACGGGGTGATTTTTACTCCGGAACTTTCAGGACTGGCCCCAGGTATTCACGGATTCCATGTGCATGAAAAACCTGATTGTGGCCCTTCCGAAAAAGATGGCAAAACCGTACCAGGCGGGGCGGCCGGGGGTCACTACGATCCGGAAAAAACTGGCAAGCATGAGGGGCCTTATGGTGCCGGCCACTTGGGCGATCTGCCGGCGTTATATGTGGGGGCAGATGGTAAAGCCACACAACCGGTTTTAGCCCCGCGATTGAAGCTGGCCGATTTAAAGGGTCGTTCCTTGATGATTCATGCCGGCGGGGATAATCATTCCGACCATCCGGCACCTCTGGGGGGCGGAGGCGCACGAGTTGCTTGCGGCGTGGTGGCGGCCGCACTCGAGCACCACCACCACCACCACTGA | H61: MALDASGASAPIGSISASSSPYGVIFTPELSGLAPGIHGFHVHEKPDCGPSEKDGKTVPGGAAGGHYDPEKTGKHEGPYGAGHLGDLPALYVGADGKATQPVLAPRLKLADLKGRSLMIHAGGDNHSDHPAPLGGGGARVACGVVAAALEHHHHHH*
A62: A0A1H8A8T3 | B62: TEST | C62: N | D62: N | E62: N | F62: N | G62: ATGATTGCGTACGATCGCCGACTGGCACCGTCTGGTGCACAGGCCTCCCTCAAAGCGGAATCTACTGGTGGAACTACACGCACGAGTCTCGTCGTGGAGGGTTTCGTTCCGAATCGTCGCTATGGTGCACACCTGCATACTGGTGCATGCGCCACAGACCCAGAAGCTTCCGGGCCTCACTATCAACACCATCCAGGCCAGGTTACGCCGAGTTCTGAGGTTTGGCTCGATTTCAAGACTGACGCTAGTGGAGCAGGTAGAGCGACGGCGCGGCATGAATGGGCACTGGATCCTGCGGCTCTGCCAAAAAGTCTGGTTATTCATGCGCAGCCCACGAAAAAAAAAGGAGAACAGGCCGGTACCGCTGGTCCGCGGATAGCCTGCTTAACCGCGGCCGCACTCGAGCACCACCACCACCACCACTGA | H62: MIAYDRRLAPSGAQASLKAESTGGTTRTSLVVEGFVPNRRYGAHLHTGACATDPEASGPHYQHHPGQVTPSSEVWLDFKTDASGAGRATARHEWALDPAALPKSLVIHAQPTKKKGEQAGTAGPRIACLTAAALEHHHHHH*
A63: A0A4R3QYV8 | B63: TEST | C63: N | D63: N | E63: N | F63: N | G63: ATGGTGGCCAACTTTGTGGCTAAAGATGGCAAAGAGGATGGACGCGCACAATTAACAGCGGCGGCGAATGGCGGCGTGCTTATTGAAGTGGAAATTTCGGGACTGCCGGCAAACAAATGGGTTGCAATACATGTCCATGAAACCGGCCGGTGTGATGCAGCGACGCATCACGAATCCGCTGGTGGACATTTCGATCCGGAAAAGGCAGAGCATGGGATTCTGGCCGCAAAAGGCCCTCACGCCGGCGATATGCCCAATCAATATGTAGGCCAAGACGGTGTCCTTCGCGCCCAGATCTTCAACGGCATGGTGACCTTGGATGGGAAGACAGACGGTATTCGTGGTCGCGCCCTCATGGTGCATGCAAATTCAGATGACTACCGCAGCCAGCCCTCACGTTGTCGCCGCAAAACGTTTTTGCGCCGTCGCCCGATTGCGACTGCACAGGTGCTTGCGGCCGCACTCGAGCACCACCACCACCACCACTGA | H63: MVANFVAKDGKEDGRAQLTAAANGGVLIEVEISGLPANKWVAIHVHETGRCDAATHHESAGGHFDPEKAEHGILAAKGPHAGDMPNQYVGQDGVLRAQIFNGMVTLDGKTDGIRGRALMVHANSDDYRSQPSRCRRKTFLRRRPIATAQVLAAALEHHHHHH*
A64: A0A5Q0JXV4 | B64: TEST | C64: N | D64: N | E64: N | F64: N | G64: ATGATAACGCTGAACGCTAAATCCAATACTGAGGTCTCAGGTAACGCCGTATTTAGCGAAGAAGATGGTATTGTTACCTTGACGGCAGTAGTAAGCGGCCTCAACCCCGGAGGGACACACGCTATCCATCTTCATGAGAAGGCTGATTGCTCATCCGATGATGGCACAAGTGCAGGAGGCCATTGGAATCCGACGGCGGAACCGCACGGAAAATGGGGTGATAAAGCGGGCTATCATAAAGGTGATATAGGAAATTTTATCGCGGACGAAAATGGTAACGGCAGCATCACCTTCGCCACCAACCAGTGGTGCATTGGCTGCGAGGACGACAATAAAAATATTATTGGCAAATCGGTCATTGTACACGCAGGTGAAGATGACTTCACCTCTCAGCCGACGGGTGCAGCTGGAGCAAGAGTATCATGTGCGGGGATCGCGGCCGCACTCGAGCACCACCACCACCACCACTGA | H64: MITLNAKSNTEVSGNAVFSEEDGIVTLTAVVSGLNPGGTHAIHLHEKADCSSDDGTSAGGHWNPTAEPHGKWGDKAGYHKGDIGNFIADENGNGSITFATNQWCIGCEDDNKNIIGKSVIVHAGEDDFTSQPTGAAGARVSCAGIAAALEHHHHHH*
A65: A0A3P9KQY6 | B65: TEST | C65: N | D65: N | E65: N | F65: N | G65: ATGGCAGTTTGCGTTTTAAAAGGGACTGGCGAGACCAATGGCGTTGTGAACTTCGAACAAGAGTCTGACAGTGCCCCCGTAAAGGTCACCGGCGAGATAAAAGGCTTAACACCGGGTAAGCATGGTTTTCACATTCATGTGTATGGTGACAATACTAACGGTTGCGTTTCAGCCGGGCCGCACTTTAATCCGTATAATAAGAACCACGGGGGACCCGAAGACGCTGAACGCCACGTAGGAGACCTGGGAAATGTGACCGCAGGCGTGAATAATGTAGCTGAGATTGATATAACTGATAAGTTAATTCGTTTATCTGGCCCAGATTCCATTGTTGGGAGAACGGTCGTGGTCTCTTTTTATTTCTTTAACTTCGTCTTGAATTTTTTGCTTTTATATAAAGCGGCCGCACTCGAGCACCACCACCACCACCACTGA | H65: MAVCVLKGTGETNGVVNFEQESDSAPVKVTGEIKGLTPGKHGFHIHVYGDNTNGCVSAGPHFNPYNKNHGGPEDAERHVGDLGNVTAGVNNVAEIDITDKLIRLSGPDSIVGRTVVVSFYFFNFVLNFLLLYKAAALEHHHHHH*
A66: A0A420XH12 | B66: TEST | C66: N | D66: N | E66: N | F66: N | G66: ATGCAGAAACTCGACCTTAAAGGGAACACCGATATAGGAATGGTAACAGTGACCGAGTCACCCTATGGGTTGGTTTTTACCCCAAATCTTACCGGTCTGACGGAGGGCGTTCATGGCTTTCACATCCATCAGAACGCATCTTGCGAACCGAAAGAACAGGACGGAAAGATGGTTTTGGGCCTGGGCGCAGGCGGTCATTGGGATCCGAATGGCACCAATAAGCACGGTTTTCCGTGGCAGGACGATTCTCATCTCGGGGAACTGCCTGTCTTAATAGTGGACCATGATGGTAATGCCAACTACCCTGTCTTAGCGCCACGTTTAAAAAAACTGGATGATATAAAAGGGCACGCGCTGATGATTCACGCAGGTGGAGATAATCACTCAGATCACCCCGCACCCCTTGGCGGAGGCGGACCTCGTATGGCCTGTGGCGTGATTGCGGCCGCACTCGAGCACCACCACCACCACCACTGA | H66: MQKLDLKGNTDIGMVTVTESPYGLVFTPNLTGLTEGVHGFHIHQNASCEPKEQDGKMVLGLGAGGHWDPNGTNKHGFPWQDDSHLGELPVLIVDHDGNANYPVLAPRLKKLDDIKGHALMIHAGGDNHSDHPAPLGGGGPRMACGVIAAALEHHHHHH*
A67: A0JC81 | B67: TEST | C67: N | D67: N | E67: N | F67: N | G67: ATGCAGCGCTCTGAAGCTCACGGCGATCGCCATGTGCGTGGCCTGGCACGCATCGTACAAGTATCGAGCGGTCGAAGCCTGGTCGATTTAATCGTTCATGGTGTTGTGCCTGGTCGTTACCATGCAACCATCCGTGAATATGGCGACCTGAAAGATGGCGCAAAGTCTACCGGAGCCGTGTGGTCTGGTGGTGAAAAAGACGCCAAAGGGATTCTGGGCACAGTAGACGTGGGGGAAGACGGACGGGGTTCCGCCTTTTTTGACAGACCGTTTCAGATATGGGAGATTATAGGCCATGCCATGGTGTTGACTAAACAGGACGAAACAACGGGGCCACTGGTTAACGATGATAATACAGTTGTGGGCGTGATCGCTCGCAGCGCTGGTGTCTGGGACAATGATAAGACCGTCTGCGCGGCCGCACTCGAGCACCACCACCACCACCACTGA | H67: MQRSEAHGDRHVRGLARIVQVSSGRSLVDLIVHGVVPGRYHATIREYGDLKDGAKSTGAVWSGGEKDAKGILGTVDVGEDGRGSAFFDRPFQIWEIIGHAMVLTKQDETTGPLVNDDNTVVGVIARSAGVWDNDKTVCAAALEHHHHHH*
... A72: A0A194PRL0 | B72: TEST | C72: N | D72: N | E72: N | F72: N | G72: ATGGTTGCCATTGCACATCTCATAAGCCAGAATGTTACAGGATCATTAACTTTTACTGAAACTGCTAATGGCATTCGTGTTAGTGGCACCATTACTGGACTGGATGTCGGTAAGTATGGTTTTCACGTTCATGAACTCGGCGACACATCAACTTGCGATGCAGCTGGGGCGCATTTTGATCCGGACGATAACACCCACGGTGGCCGCGATCATTCTGTTCGACATGTAGGTGATTTGGGAAATGTACAGTTTGTTGGAAACGAAAATCCAGTAGCTAATATTGACTTCGTGGACAATATTATTAGTCTCCGCGGCCGTAATAGTATTATTGGCCGCACGCTGGTATTACATGAACAGGAAGATGATCTGGGCTTGGGCGGTAATGAAGCCTCGCTTAATACTGGGAATGCCGGGCCTCGCGTTGCATGCGGTGTCATCGGCATACGTAGTCCATCAGGGCCTTGGAATGCGGCCGCACTCGAGCACCACCACCACCACCACTGA | H72: MVAIAHLISQNVTGSLTFTETANGIRVSGTITGLDVGKYGFHVHELGDTSTCDAAGAHFDPDDNTHGGRDHSVRHVGDLGNVQFVGNENPVANIDFVDNIISLRGRNSIIGRTLVLHEQEDDLGLGGNEASLNTGNAGPRVACGVIGIRSPSGPWNAAALEHHHHHH*

Sheet round1_MDH
A1: Name | B1: Group | C1: Activity (20 μg/mL) | D1: Expression | E1: Solubility | F1: Purification | G1: expressed sequence | H1: tagged sequence
A2: N268_0.879 | B2: ASR | C2: N | D2: Y | E2: Y | F2: Y | G2: ATGAAGAAAATCTCGATAATTGGCGCTGGTCGCGTAGGGGAATCAACTGCTCAGATCCTGGCGCAGAAAGAATTGTGCCGAGAAATTGTTCTTCTCGATATAAGAGAAGGAGTTGCGAAGGGCGCAGCCCTTGACATACAGGAGTCCGCTCCAATTTTTGGATTCGACACTCGCGTTACAGGCTCAACTGATTCCGCTGCTATTGCTGATAGTGATCTGGTTATAATTACGGCCGGTATTCCACGGAAACCTGGCATGTCTCGCTCCGATGTTCTGGATACCAATCTGGCCATCATAGATGAAATCGTTGATGAGGTGATGAAGTATGCGCCTGACGCAATGTTATTATTGGTTACAAACCCCGTGGATGTGTTAACGTACCATGCCTGGAAAAGAACCGGTTGGCCCCGTAACCGTGTCTTCGGTCAGGCCGGCGTCCTTGACTCAGCTCGCATGGCGAGCTTCATTGCAATGGAAACTGGCTTTAGCGTGAAAGATATTAGTGCGATGGTTCTCGGCGGCCACGGTGACACCATGGTCCCAATGACCCGCTATACTACCATCAACGGGATCCCTGTCACACATTTTCTGGATCAGGAAACAATTGAACAAATCGTTGAACGCACACGTCATGGTGGCGCCGAAATTCTTGCGTTAAGACAGACGTCTTCCGCATATGATGCCCCAGCTGCGGCTGTTGCCGCCATGGTCGACGCCATTTGCCATGATCGTAAGCGGATCTTACCGTGCGTTGCAATCTTGGAGGGTGAATATGGACAGCGCGATATAGCAATGGGTGTACCCGTGGTGCTTGGACGCAACGGGGTTGAACGCGTTATTGAACTTCCGTTAACAGAGGAAGAGCAAGCTGAGTTCAAACAGTCAGCAGAGGCGGTGCGAGCGGATATTGAAAGATTGAAAAAACTGGCGGCCGCACTCGAGCACCACCACCACCACCACTGA | H2: MKKISIIGAGRVGESTAQILAQKELCREIVLLDIREGVAKGAALDIQESAPIFGFDTRVTGSTDSAAIADSDLVIITAGIPRKPGMSRSDVLDTNLAIIDEIVDEVMKYAPDAMLLLVTNPVDVLTYHAWKRTGWPRNRVFGQAGVLDSARMASFIAMETGFSVKDISAMVLGGHGDTMVPMTRYTTINGIPVTHFLDQETIEQIVERTRHGGAEILALRQTSSAYDAPAAAVAAMVDAICHDRKRILPCVAILEGEYGQRDIAMGVPVVLGRNGVERVIELPLTEEEQAEFKQSAEAVRADIERLKKLAAALEHHHHHH*
A3: N495_0.993 | B3: ASR | C3: Y | D3: Y | E3: Y | F3: Y | G3: ATGGCGGCTATGACAACGATGACAAAAACCCCAGTGACCGTGACGGTCACTGGGGCCGCGGGCCAGATTGCGTACGCATTGCTCTTTCGCATCGCATCAGGCGCTGTTTTTGGTCCGGACACCCCCGTACGGTTGCGCTTGTTGGAAATCCCTCAGGCCGTACGCGCCGCTGAGGGGGTAGCCATGGAACTGGACGATTGCGCCTTTCCATTATTAGCGTCGATAGATATAACTGATGATCCGGCAACAGCTTTTGATGGCGCCAACGCCGCGTTACTGGTTGGGGCACGACCGCGTGGTGCTGGTATGGAGCGAGCTGATCTCTTGGCCGCAAATGGGGGTATTTTTGGCCCGCAGGGTCGTGCCATTAACGATCATGCAGCTGACGACGTTCGTGTGCTCGTTGTCGGAAATCCGGCGAACACCAACGCACTGATTGCAGCTAGCCATGCCCCTGATGTGCCTGCGGAACGATTCACTGCCATGATGCGTCTGGATCATAATCGCGCCCTTGCCCAGTTGGCGGCAAAACTGGGGGTCCCGACCTCAGATTTAGATCGTATGACTGTGTGGGGCAATCATTCGGCGACACAATTTCCCGATGTGACATATGCTACAGTTGGCGGTCAGCCGGTTGCTGATAAAGTTGACCAAGCTTGGCTTGAAGATGAATTCATTCCACGCGTTGCGAAGCGAGGAGCCGAAATAATTGAAGTCCGCGGGTCATCATCTGCGGCATCTGCAGCTTCAGCAGCCATCGATCACATGCGCGATTGGGTACAGGGAACCCCTGAAGGCGATTGGACCTCGGTAGCCCTGCCGTCAGACGGATCGTATGGAATACCTGAAGGATTGGTTTCTAGTTTTCCTTGTAGAAGTAGTGATGGGGAATGGGAAATCGTGCAGGGGCTGGAGATTTCAGATTTCCAGCGTGCGCGGATTGACGCTTCTGTGGCGGAACTGGTTGAAGAGCGGGACGCAGTGCGTGAGCTCGCGGCCGCACTCGAGCACCACCACCACCACCACTGA | H3: MAAMTTMTKTPVTVTVTGAAGQIAYALLFRIASGAVFGPDTPVRLRLLEIPQAVRAAEGVAMELDDCAFPLLASIDITDDPATAFDGANAALLVGARPRGAGMERADLLAANGGIFGPQGRAINDHAADDVRVLVVGNPANTNALIAASHAPDVPAERFTAMMRLDHNRALAQLAAKLGVPTSDLDRMTVWGNHSATQFPDVTYATVGGQPVADKVDQAWLEDEFIPRVAKRGAEIIEVRGSSSAASAASAAIDHMRDWVQGTPEGDWTSVALPSDGSYGIPEGLVSSFPCRSSDGEWEIVQGLEISDFQRARIDASVAELVEERDAVRELAAALEHHHHHH*
A4: N296_0.884 | B4: ASR | C4: Y | D4: Y | E4: Y | F4: Y | G4: ATGAGCAGCATGTCGGCTATGTCAGAAACTATGAAGAAAGTGAGTATTATCGGAGCCGGTAATGTAGGTAGCACAATCGCTATGTTAATTGCGTTGAATGAGCTTGCAGACGTAGTTCTTGTAGATATTGTTGAGGATCTCGCCCAGGGGAAAGCTCTCGACCTGATGCAGGCGGCGGCAGTTTTCAATTCCGATGCAAAGATTGTTGGGACAAACGATTACGAGGAAATAAAAGGCAGTGATATTGTAGTGATTACAGCTGGAATCGCTCGCAAACCGGGCATGTCCCGTGAGGATTTACTGAATACGAACGCCAAGATTGTTAAAGACGTGGCAAAGAACATCAAAAAATACGCGCCGGACTCAATTGTCATAGTTGTATCTAATCCCTTAGACGTAATGACGTACCTGGCTTATAAGGTGACTGGCTTCAACCGTAACCGGGTGATGGGCATGGCTGGTGTGTTAGATAGTGCTCGCTTCCGTTATTTTATTGCCCAGAAGCTTAATGTGTCTGTCAATGACATTGAATCAATGGTCTTAGGCAGCCATGGCGACTCAATGGTACCACTTGCAAGTCAGACTACGGTTAATGGGCGCCCGATCAAAGAATTTTTAAATAAGGAGAAAATTGAGGAGATTGTTGAAAAAACCCGCAACGGGGGAGCTGAGATCGTTAGTCTCCTGAAAACGGGCTCTGCCTACTATGCACCCGCGTCCGCAGTTTATCTGATGGTTAAAGCCATCCTCAAAGATAAAAAAGAAATACTTCCGGCCTGTGTTTATCTCGAAGGAGAATACGGCCTGAAAGACGTCTGCATCGGTGTTCCGGTTAAACTCGGAAAAAATGGTATCGAAAAGATTATTGAATTAGAACTGAGTGAGGAAGAAAAAGAGGCGTTACAGAAAAGCGCCGAAGCTATTAAAGAGAACATTAATCAGCTTGCGGCCGCACTCGAGCACCACCACCACCACCACTGA | H4: MSSMSAMSETMKKVSIIGAGNVGSTIAMLIALNELADVVLVDIVEDLAQGKALDLMQAAAVFNSDAKIVGTNDYEEIKGSDIVVITAGIARKPGMSREDLLNTNAKIVKDVAKNIKKYAPDSIVIVVSNPLDVMTYLAYKVTGFNRNRVMGMAGVLDSARFRYFIAQKLNVSVNDIESMVLGSHGDSMVPLASQTTVNGRPIKEFLNKEKIEEIVEKTRNGGAEIVSLLKTGSAYYAPASAVYLMVKAILKDKKEILPACVYLEGEYGLKDVCIGVPVKLGKNGIEKIIELELSEEEKEALQKSAEAIKENINQLAAALEHHHHHH*
A5: N556_0.961 | B5: ASR | C5: Y | D5: Y | E5: Y | F5: Y | G5: ATGACGGAGCCAATTCGCGTTCTGATTACCGGGGCAGCGGGCCAGATTGGATATAGTCTGTTATCCATGGTTGCAAAAGGTGATATGTTCGGCCCGGACCAGCCCATTATTCTCCACCTCTTAGACATTCCGCCCGCAATGGAAGCTCTGAAGGGTGTTGTAATGGAGTTGCAGGACTGTGCATTTCCTTTGTTACAGGAAGTTGTTCCCACAACTGATCCGGAGGAAGCATTTAAAGACGTTGATGTGGCCATTTTAGTTGGCGCGATGCCGCGCAAAGAGGGCATGGAAAGAAAAGATTTGTTGGAAAAAAATGTCGCGATCTTTAAAGCCCAGGGTGAAGCGCTTGATAAGTATGCCAAGAAGACAGTCAAAGTCCTGGTGGTTGGCAATCCAGCAAACACGAACTGTCTGATCCTGTCGAAATATGCGCCCTCTATTCCGAAAGAAAATTTCACTGCGTTGACACGTTTAGATCATAATAGAGCTATTGCACAGATAGCAGAGCGCTTGGGCGTCTCGGTTAGTGACGTAAAAAACGTGATAATCTGGGGAAATCATAGCTCTACTCAGTTTCCGGATGTATCACATGCCACTGTCAACGTTAATGGTAAGGAAAAACCAGTGCGAGATGCAGTCAATGATGATGCTTGGTTGAAAGGTGAGTTCATTTCCACCGTACAGAAGCGAGGCGCGGCGGTCATTGCGGCGCGTAAACTGAGCTCGGCCATGTCGGCGGCAAAAGCGATCTGCGATCATATGCATGACTGGGTACTGGGTACTCCTGAGGGTGAATGGGTGTCCATGGGTGTGACTAGTGATGGCTCCTATGGGGTGCCTAAAGACTTGATTTTTTCCTTTCCAGTGACATGCAAAAACGGCAAATGGAAAATTGTGCAGGGTCTGAAGATAGACGATTTTGCCCGTGAAAAACTGGACGCAACTGCTAAGGAACTGGAGGAGGAAAGAGACATGGCTTTAGAAGTTTGCGCGGCCGCACTCGAGCACCACCACCACCACCACTGA | H5: MTEPIRVLITGAAGQIGYSLLSMVAKGDMFGPDQPIILHLLDIPPAMEALKGVVMELQDCAFPLLQEVVPTTDPEEAFKDVDVAILVGAMPRKEGMERKDLLEKNVAIFKAQGEALDKYAKKTVKVLVVGNPANTNCLILSKYAPSIPKENFTALTRLDHNRAIAQIAERLGVSVSDVKNVIIWGNHSSTQFPDVSHATVNVNGKEKPVRDAVNDDAWLKGEFISTVQKRGAAVIAARKLSSAMSAAKAICDHMHDWVLGTPEGEWVSMGVTSDGSYGVPKDLIFSFPVTCKNGKWKIVQGLKIDDFAREKLDATAKELEEERDMALEVCAAALEHHHHHH*
A6: N311_0.998 | B6: ASR | C6: N | D6: Y | E6: N | F6: N | G6: ATGCCAACCGAATCATTTAGAGCCCAGAGACTTAAGAAATTAGCAATGGTAGGTGCGGGCAACGTAGGCTCCACGCTGGCTCAATTGGCCGCTCATAGCGAAATTTCAGAGGAAATCACCTTGGTTGATATAGTTCCGGGTCTGGCGGAATCAATAGCATTAGATCTTAACCATGCAGCTGGAATCACCGGATCTGCAGCGCGGATAAATGGTACTACAGATTTAGACCTTGTTCACGGTGCTGATGTTGTGGTTGTCACCGCTGGAAGACCTCGCACACCAGGTATGTCTCGTTCAGATCTGCTCAAAATTAATGCCCGTGTCATCAAGGGAGTGGCGGAGGCAATTAAAAAGTATGCGCCGGATGCCGTCGTGATCGTTGTGACAAATCCGTTGGATGAAATGACTTCGGTAATGTTAAATGTTACGGGTTTTGATCGCGAAAAAGTCATTGGTATGGCGGGCACCCTTGACTCAGCGCGTTTTCGTGATGCCCTGGCCCAAGCCGCGGGTGTGTCCGTGGCTGATGTCGAAGCGATGACTTTAGGAAGTCATGGTGATGAAATGGTACCCATTGTGAGTCAGGCCACCATAAAAGACCGGCCCATCGGTGAACTGCTTAACGAAGAAACCATTGAAAGCTCTGCCGAACGCACAATAGACGGTGGTGCAGAGGTCGTGCGTTTGCGTAAAACTGGAAGCGCTTACCTGGCCCCAGCTTATGCGACAATAGAGCTGATTGAGCATATGCGAGGTGACCGAAACGGAGCTATACCGGCCTCTGTTCTTCTGGAGGGCGAGTATGGGATTACGGATGTTGTCGTTGGAGTTCCCTGTAAATTAGGTAAAAATGGAGTCGCGGAGATTGTAGAATTGACACTGTCTGAATCTGAGAAACAAGCGTTACAGAAGGCCGCAGCAGCAATAAAACAACGTTTAGGAGAACTGGCGGCCGCACTCGAGCACCACCACCACCACCACTGA | H6: MPTESFRAQRLKKLAMVGAGNVGSTLAQLAAHSEISEEITLVDIVPGLAESIALDLNHAAGITGSAARINGTTDLDLVHGADVVVVTAGRPRTPGMSRSDLLKINARVIKGVAEAIKKYAPDAVVIVVTNPLDEMTSVMLNVTGFDREKVIGMAGTLDSARFRDALAQAAGVSVADVEAMTLGSHGDEMVPIVSQATIKDRPIGELLNEETIESSAERTIDGGAEVVRLRKTGSAYLAPAYATIELIEHMRGDRNGAIPASVLLEGEYGITDVVVGVPCKLGKNGVAEIVELTLSESEKQALQKAAAAIKQRLGELAAALEHHHHHH*
A7: N587_0.820 | B7: ASR | C7: Y | D7: Y | E7: Y | F7: Y | G7: ATGCGTTCCGCAGCTGCCGGGAGCGTCCCTAATAGCAAAGTGGCGGTCCTCGGGGCCGCCGGTGGTATAGGTCAGCCTTTATCGCTCCTGCTCAAACAGAGTCCGTTAGTTAGCGAGCTCGCTCTGTATGACATCGCAAATACTCCAGGCGTAGCGGCCGATCTGTCTCACATAAACACCCCGGCCAAAGTCAAAGGCTATGTTGGTGCCGAGCAGTTGGGCGAAGCGCTGAAAGGTTGTGATGTGGTCGTGATTCCTGCTGGGGTTCCGCGTAAGCCTGGCATGACTAGAGACGATTTGTTTAATATCAATGCGGGAATTGTGAAGAATTTGGCTGAAGGCGTTGCCAAGCATTGTCCGGAGGCCATGATAGCTATAATTTCTAACCCAGTTAACAGCACGGTCCCGATCGCAGCAGAAGTTCTGAAAAAAGCCGGAGTGTATAACCCTAAACGACTTTTCGGCGTCACAACACTCGATGTTGTGCGCGCTAAGACGTTCGTCGCAGAAGCAGCGGGTTTGGATCCGAACGACGTGAACGTGCCGGTTGTCGGAGGGCACGCCGGCATTACGATATTGCCATTACTGTCCCAGGCCACGCCAAAAGCAACATTTACGGATGAAGAGATTGAAGCATTAACCAACCGGATTCAGGATGCAGGTACTGAAGTCGTAGAAGCCAAGGCAGGAGCAGGTAGCGCCACATTGTCCATGGCATACGCCGGCGCACGCTTCGCCGATTCTTGTCTTCGGGCACTTAATGGGGAGAGCGGCGTGGTAGAATGCGCATTTGTGGAATCAGATGTCACGGAAGCGCCATTCTTTGCCTCTCCAGTACGCCTGGGCAAGAATGGAGTGGAAGAGATTTTGGGTCTGGGGAAGCTGAGCGATTTTGAACAGAAAAATCTCGAAGCGATGCTGCCGGAACTCAAAGCCAGCATTCAGAAAGGTGTCGATTTCGTAGCGGCCGCACTCGAGCACCACCACCACCACCACTGA | H7: MRSAAAGSVPNSKVAVLGAAGGIGQPLSLLLKQSPLVSELALYDIANTPGVAADLSHINTPAKVKGYVGAEQLGEALKGCDVVVIPAGVPRKPGMTRDDLFNINAGIVKNLAEGVAKHCPEAMIAIISNPVNSTVPIAAEVLKKAGVYNPKRLFGVTTLDVVRAKTFVAEAAGLDPNDVNVPVVGGHAGITILPLLSQATPKATFTDEEIEALTNRIQDAGTEVVEAKAGAGSATLSMAYAGARFADSCLRALNGESGVVECAFVESDVTEAPFFASPVRLGKNGVEEILGLGKLSDFEQKNLEAMLPELKASIQKGVDFVAAALEHHHHHH*
A8: N342_0.976 | B8: ASR | C8: Y | D8: Y | E8: Y | F8: Y | G8: ATGAATAAACGTGTTAAAGTTGCTGTAACTGGAGCTGCAGGTCAAATAGGTTATGCCCTCTTATTTCGCATAGCGTCAGGTCAGATGTTCGGTCCCGACGTCGAAGTTGAACTCCAATTGCTGGAATTGGAACAAGCCTTACCCGCTCTTCAGGGTATAGTTATGGAGCTGGAAGACTGCGCTTTCCCTTTACTTAAAAATATTGTTTGCACCAGCGACCTTAATGCGGCGTTTAAAGATGTGAATTGGGCGATTTTAGTGGGGTCCGCCCCGCGCAAAGCGGGCATGGAACGGAGCGACCTTTTAAAAATTAACGGGGGTATCTTTACCGCACAAGGCAAAGCGATAAACGATCACGCGGCTGATGATGTCCGTGTGTTTGTGGTAGGTAATCCTTGTAATACCAACTGTCTTATTGCCATGCACAATGCACCGGATATTCCCAGAGATCGTTTCTATGCAATGACAATGCTGGATGAGAACAGAGCGCGTACTCAACTGGCTAAAAAAGCAGGCGTCCCGGTTACTGAAGTCAATAATATGGCAATTTGGGGCAATCACAGTTCTACCCAGTACCCCGACTTCTATCACGCGAAAATCAATGGTAAACCAGCGACCGAAGTTATCAAGGATGAAGCATGGTTACAAAATGAGTTCATCCCTACCGTCCAGCAACGTGGAGCTGCGGTCATCAAAGCCAGAGGCGCCTCCTCTGCCGCGTCTGCAGCTAACGCAGCCCTGGATTCCGTCCACAATCTGATTCACGATACTCCGGCCGGTGAGTGCTTTTCCGTGGCGCTCTGTAGCAACGGGCAGTATGATGTAGATGAAGGTTTGATATTCAGCTATCCGTGCCGTACAGAAAACGGGAAACTGAAGGTCGTTGAGGGTATCGAGCATAATGACTTCGCTCAGGAAAAATTTCAGATTACCCTTGATGAATTACGTAAAGAGCGTGATGCGGTCAAAGACCTGGCGGCCGCACTCGAGCACCACCACCACCACCACTGA | H8: MNKRVKVAVTGAAGQIGYALLFRIASGQMFGPDVEVELQLLELEQALPALQGIVMELEDCAFPLLKNIVCTSDLNAAFKDVNWAILVGSAPRKAGMERSDLLKINGGIFTAQGKAINDHAADDVRVFVVGNPCNTNCLIAMHNAPDIPRDRFYAMTMLDENRARTQLAKKAGVPVTEVNNMAIWGNHSSTQYPDFYHAKINGKPATEVIKDEAWLQNEFIPTVQQRGAAVIKARGASSAASAANAALDSVHNLIHDTPAGECFSVALCSNGQYDVDEGLIFSYPCRTENGKLKVVEGIEHNDFAQEKFQITLDELRKERDAVKDLAAALEHHHHHH*
A9: N574_0.023 | B9: ASR | C9: N | D9: Y | E9: N | F9: N | G9: ATGCGAAGTGCGGCAGCAGGTTCGGTTCGTAATATGAAAGTCGCGGTCCTCGGAGCAGCCGGCGGCATTGGGCAGCCTCTGAGCTTATTACTTAAACAGTCTCCACTTGGATCGGAGCTGGCGTTATACGATATTGCACCAATAACCCCTGGTGTGGCGGCAGACTTGAGTCATATTAACACACCGGCCGGTGTGACGGTGCGCGTAAGTGGCGAAGACTTAGATGAAGCGTTGAAAGGTGCCGATGTTGTTGTTATTCCAGCGGGCGTGCCGCGTAAACCTGGCATGACTCGTGACGACCTGTTTAATACAAATGCAGGGATTGTGAAGAATCTTGCCGAGGCAATTGCAAAACATTGTCCGGAGGCAGCCATTGCTATCATTACCAATCCGGTTAACACGACTGTGCCGATAGCTGCAGAGGTACTGAAAAAACATGGCGTTTACAACCCAAAACGCCTGTTTGGAGTTACAACGCTTGATGTGGTGAGAGCGAAGACGTTTGTAGCTGAAGCCAAGGGTTTGGATGTAAACGATGTTAATGTACCGGTGATCGGGGGCCATGCAGGCATTACGATTCTGCCGTTGCTCAGCCAGGTTACGCCGTCAGGAGCGCCGACGGCCCAGTTCACAGACGATGAAGAGATAGAAGCCCTCACTAACCGAATTCAAGATGCTGGCACGGAGGTTGTTGAGGCGAAAGCAGGAGCCGGCTCCGCGACCCTGAGTATGGCCTATGCGGCGGCGCGCTTTGCAAATTCCCTGCTTCGTGCCCTTAATGGCGAAGAAGGCGTTGTAGAATGCGCTTTTGTCGAATCCGATGTCACAGAGGCTCCGTTTTTTGCATCACCAGTGGAATTAGGTAAGGATGGCGTTGAAGAAATCTTGCCTCTGGGAGAATTGTCCGACTTTGAAAAAAAAGCCCTCGAGGAGATGCTGCCCGCACTGAAAGCAAACATTAAAAAAGGCGTTGACTTTGTCGCGGCCGCACTCGAGCACCACCACCACCACCACTGA | H9: MRSAAAGSVRNMKVAVLGAAGGIGQPLSLLLKQSPLGSELALYDIAPITPGVAADLSHINTPAGVTVRVSGEDLDEALKGADVVVIPAGVPRKPGMTRDDLFNTNAGIVKNLAEAIAKHCPEAAIAIITNPVNTTVPIAAEVLKKHGVYNPKRLFGVTTLDVVRAKTFVAEAKGLDVNDVNVPVIGGHAGITILPLLSQVTPSGAPTAQFTDDEEIEALTNRIQDAGTEVVEAKAGAGSATLSMAYAAARFANSLLRALNGEEGVVECAFVESDVTEAPFFASPVELGKDGVEEILPLGELSDFEKKALEEMLPALKANIKKGVDFVAAALEHHHHHH*
A10: N324_0.815 | B10: ASR | C10: Y | D10: Y | E10: Y | F10: Y | G10: ATGACGAAACCGATCCGTGTTGCTGTCACCGGTGCTGCGGGCCAAATTGGTTACTCACTGTTGTTTCGGATCGCGTCAGGGGAGATGTTCGGGCCGGACCAGCCAGTCATCCTGCAGTTACTGGAGATTCCGCCCGCCATGAAAGCCTTGGAAGGAGTAGTCATGGAACTGGATGATTGTGCGTTCCCGCTCCTCCATGGGATTGTTATTACCGACGATCCAAACGTCGCGTTTAAAGATGTAAACTGGGCTCTGTTAGTAGGATCTAAACCGAGAGGACCGGGCATGGAACGCGGCGATCTGATCAAAGAAAATGGGCCAATATTTGTAGGTCAAGGTAAAGCCTTAAATGACAACGCAGCCTCGGATGTTCGCGTGTTGGTAGTCGGAAACCCCTGTAATACCAATTGTCTGATTGCCATGCATAATGCCCCGGACATCCCTCGCGATCGCTTCACGGCGATGACCAGACTTGACCAAAATCGGGCAAAAGCGCAGCTGGCGAAAAAGGCCGGGGTCGCGGTCTCTGAAGTGTCCAACATGGCAATATGGGGAAACCATTCGGCCACTCAGTTTCCGGATTTTGAGAATGCCAAGATAAATGGTAAGCCGGCGACCGAGGTCATTACTGATCGTGCGTGGTTGGAAGGTGAATTTATTTCGACGGTACAGAAACGTGGTGCAGCAATAATTGACGCTCGTGGCGCTTCGTCGGCAGCAAGTGCGGCGAATGCTGCTATTGATCACGTTCGCTCTTTGGTTACACCAACCCCGGCTGGAGACTGGTTTAGCGTGGCTGTTCCAAGTGATGGTTCATATGGTATTCCAGAAGGTCTGATTTTTTCCTTTCCGGTTCGGTCCAATGGCAATGGTAATTATGAGATTGTGCAAGGTCTTGAGCTGTCGGATTTTGCACGCGAGAAAATCGACGCTACTGTGGATGAGTTAGTTGAAGAACGAGATGCGGTGAAAGATTTACTTGCGGCCGCACTCGAGCACCACCACCACCACCACTGA | H10: MTKPIRVAVTGAAGQIGYSLLFRIASGEMFGPDQPVILQLLEIPPAMKALEGVVMELDDCAFPLLHGIVITDDPNVAFKDVNWALLVGSKPRGPGMERGDLIKENGPIFVGQGKALNDNAASDVRVLVVGNPCNTNCLIAMHNAPDIPRDRFTAMTRLDQNRAKAQLAKKAGVAVSEVSNMAIWGNHSATQFPDFENAKINGKPATEVITDRAWLEGEFISTVQKRGAAIIDARGASSAASAANAAIDHVRSLVTPTPAGDWFSVAVPSDGSYGIPEGLIFSFPVRSNGNGNYEIVQGLELSDFAREKIDATVDELVEERDAVKDLLAAALEHHHHHH*
A11: N594_0.986 | B11: ASR | C11: N | D11: Y | E11: N | F11: Y | G11: ATGGCCGCTAGCTCTGCTCGCAATGGTCGCGCGCGCCGTGTGGCAGTTGTCGGCGCAGGGCACGTTGGGATGATAACAGCTATGCGCCTGGCGGAAAGCGACTTATTTGATGAAGTCGTCTTAGTTGACATTGCTGAAGGTCGCGCGGCGGGCATCGCTTTGGATCTGACGCATGCAGCACCGCTCCTGGGATTTGCGACACGCATCCGTGGGACCAATACGCTGGAAGAAGCGGGTTCAGCGGATTACGTGGTAATTACAGCAGGTCGCCCTAGACAGCCGGGCATGAGCCGTACGGATCTTGTGGGGACGAACGCAGCCATTGTCGGCGACGTTGCGCAGGGTATCGCAAGAACCAGTCCCGATGCAGTTCTTGTTGTAGTTACCAATCCGCTGGATGAAATGACCCAACATGCATGGCAGGTTACGGGGCTGCCTCCAGAAAGAGTGATTGGTATGGCGGGCGTATTAGACAGCGCACGCTTTCAGGCATTAGCAGCGTTGGCGGGCAACGTACGACCACATGAAGTAGAAGCTCTCGCGCTTGGAAGCCATGGTGATGAAATGGTCATTCCCCTGAGCCAAGCGACCGTGGGTGGTCGCCCGATAGAAGAACTTCTGGATGCCACAACATTGGAGGCAATTGTTGATCGAACACGAGATAGCGGGGCGGAGGTTGTGGGTTTATTAAAATCAGGTTCTGCATTCTTTGCTCCGGGGGCGTCGGCTGCGCGTATGGTTCTGGCGATGGTTCGTGACTCCGGGGAAGTCATGCCAGCCGCGGTACTGCCTGACGGCGAGTATGGCATCACCGATGTTTATGTTGGTCTGCCCGTGCGGTTAGGTCGGAACGGCGTACGTGAGATCGTCGAACTTCCTTTACGCCCGGCCGAATTACAAGCACTTCAGGCGGCGGCAGCGCGGATAGCGGAAAGAATTGATGAACTGGCTGCAGTCGCGGCCGCACTCGAGCACCACCACCACCACCACTGA | H11: MAASSARNGRARRVAVVGAGHVGMITAMRLAESDLFDEVVLVDIAEGRAAGIALDLTHAAPLLGFATRIRGTNTLEEAGSADYVVITAGRPRQPGMSRTDLVGTNAAIVGDVAQGIARTSPDAVLVVVTNPLDEMTQHAWQVTGLPPERVIGMAGVLDSARFQALAALAGNVRPHEVEALALGSHGDEMVIPLSQATVGGRPIEELLDATTLEAIVDRTRDSGAEVVGLLKSGSAFFAPGASAARMVLAMVRDSGEVMPAAVLPDGEYGITDVYVGLPVRLGRNGVREIVELPLRPAELQALQAAAARIAERIDELAAVAAALEHHHHHH*
A12: N397_0.287 | B12: ASR | C12: Y | D12: Y | E12: Y | F12: Y | G12: ATGAAACCGCCGATTAGAATTGCGATCACCGGCGCAGCCGGTCAGATTGGCTATAGTCTGCTGTTCCGGATCGCCGCAGGGGATATGCTCGGCAAGGATCAGCCGATTATTTTACAACTGCTGGACATCCCGCAAGCGCAACAGACCCTGAAAGGCGTGGTTATGGAACTGGAAGATTGCGCATTCCCACTGTTGCATGATGTAATTACAACAGACGATCCTAAGGTCGCGTTCCATGATGCGGATATAGCGATCTTAGTGGGCGCTCGTCCGCGAGGTAAAGGCATGGAACGGAAAGATTTGCTCGAAGCAAACGGTGAAATCTTTTCCGCTCAGGGAAAGGCACTTAACGAGGTGGCGAACCGAAATGTTAAAGTTCTCGTCGTGGGAAACCCTGCCAATACAAACGCCCTGATTACCATGAAAAATGCACCCGATTTAAATCCGAAGAATTTTTCAGCAATGATGCGGTTGGACCATAACAGAGCATTATCCCAAGTGGCACAAAAAGTGGGGAAGCCTGTATCTTCCATCCGCAAGATGATTGTCTGGGGTAATCATAGCGCCACCCAATATCCAGACTTAAGTCATGCTGAAATTGATGGTCAAAAAGTCCTGACCCTCATCAACGATCAAGCCTGGATTGAAAACTATTTTATTCCTACCGTTCAGAAACGCGGTACCGCAATCATCGAGGCACGGGGTCTGTCAAGTGCAGCGTCGGCGGCTAACGCGATTATTAACCACATGCACGACTGGATATTTGGTACCCGGGAGAACGATTGGGTGAGCATGGGTATACCGAGTGATGGATCCTATGGAATTCCTGAGGGCGTAATCTACGGCTATCCGGTCACGTGTCAGAACGGGGCCTACAAAATTGTGCAGGGTCTGGAAATATCTGACTTTTCCCGCGAAAAAATGCAGGCTAGCTATCAGGAACTTCTGGAAGAACGCGACGCCATAAAACACTTACTTGCGGCCGCACTCGAGCACCACCACCACCACCACTGA | H12: MKPPIRIAITGAAGQIGYSLLFRIAAGDMLGKDQPIILQLLDIPQAQQTLKGVVMELEDCAFPLLHDVITTDDPKVAFHDADIAILVGARPRGKGMERKDLLEANGEIFSAQGKALNEVANRNVKVLVVGNPANTNALITMKNAPDLNPKNFSAMMRLDHNRALSQVAQKVGKPVSSIRKMIVWGNHSATQYPDLSHAEIDGQKVLTLINDQAWIENYFIPTVQKRGTAIIEARGLSSAASAANAIINHMHDWIFGTRENDWVSMGIPSDGSYGIPEGVIYGYPVTCQNGAYKIVQGLEISDFSREKMQASYQELLEERDAIKHLLAAALEHHHHHH*
... A19: N673_0.992 | B19: ASR | C19: Y | D19: Y | E19: Y | F19: Y | G19: ATGAGAAAGAAGATAACCGTCGTTGGGGCGGGCAACGTGGGAGCCACTGCAGCGCAGCTGATAGCGCAGAAAGGTTTAGCCGACGTGGTTTTAATAGATATTGTGGAGGGCATGCCGCAGGGTAAAGCTCTGGATATGTTAGAGGCCTGTCCGTTATGGAATTCGTCAGCCCGGATTACCGGGACCAATGACTATGCTGACACGGCCGGATCAGATATTGTCGTCATCACGGCCGGTTTGGCGAGAAAACCTGGTATGTCGCGGGACGACTTACTGCATGCCAATGCAAAAATTATCAAGGATGTGGCCGGTGAAATCGCGAAAACTTCTCCAGACGCGATCATTATTGTAGTAACGAATCCCATGGATGCCATGGCACACGTGGCGCGCAAAGTGACCGGTTTTCCGCACAATAGAGTGATTGGTATGGGTGGTGTGTTGGACTCGGCCCGTATGCGTACCTTTATCGCGTTGGAACTGGGAGTGAGTCCTGAAGACGTGCAGGCTATGGTATTAGGTGGCCATGGTGATCAGATGGTGCCGTTACCGAGATTTACTACCGTTAAAGGAATACCTATCACAGAACTGCTGCCGGAAGAGAAAATTGAGCAGATCATAGAGAGAACCCGAAACGGTGGAGCCGAGATTGTCTCACTTCTGAAAACCGGGAGCGCTTATTACGCGCCTGCCGCAAGTACAGTCGAAATGGTCGAAGCTATCCTGCGGGACAAGAAACGGATACTCCCTTGTGCCGCCTACTTAGATGGGGAATATGGAATTAAAGGTTTATACGTGGGCGTTCCTGTGATTCTGGGGAAGAAAGGAGTGGAAAAAATTATTGAGCTGGAGCTGACGGAAGAAGAAAAAGCTGCACTCGATAAATCAGCTGAAGCAGTTAAAGAGTTAATTGAAAAACTGAAAGCGGCCGCACTCGAGCACCACCACCACCACCACTGA | H19: MRKKITVVGAGNVGATAAQLIAQKGLADVVLIDIVEGMPQGKALDMLEACPLWNSSARITGTNDYADTAGSDIVVITAGLARKPGMSRDDLLHANAKIIKDVAGEIAKTSPDAIIIVVTNPMDAMAHVARKVTGFPHNRVIGMGGVLDSARMRTFIALELGVSPEDVQAMVLGGHGDQMVPLPRFTTVKGIPITELLPEEKIEQIIERTRNGGAEIVSLLKTGSAYYAPAASTVEMVEAILRDKKRILPCAAYLDGEYGIKGLYVGVPVILGKKGVEKIIELELTEEEKAALDKSAEAVKELIEKLKAAALEHHHHHH*
A20: 2491 | B20: ESM-MSA | C20: N | D20: Y | E20: N | F20: N | G20: ATGGCGCGCAAAATAACAGTAGTTGGCTCGGGAAATGTGGGCGCCACGGCAGCCCATTGGATTGCCGAGAAGGAACTCGGGGATGTTGTTCTGATAGACATTGTTGAGGGGATGCCGCAGGGTAAAGCGTTAGATCTTGCTCAGAGTCTTCCAGTGCAGGGCTTCGATTGCAAAGTTGTTGGAACTAACGATTATAAGACCACCGAAGATTCTGATATAGTTGTAATTACCGCAGGGTTGGCTCGCAAACCGGGGATGAGCCGGGATGATCTGTTAGAAAAGAATCAGGAGATAGTTAAAGGTGTCACGGAGGCAGTAGTGAAATATAGTCCTCAGGCCATTATTATTGTTGTTACGAACCCTCTGGACGCCATGGTCCAAGTCTGTTATAAATCCAGCGGCTTACCACGTGAGCGCGTCATCGGAATGGCTGGTGTGTTGGATAGCGCTAGATTTAGAACATTTCTCGCTATGGAGCTTGGTGTATCGGTTGAAGATGTACAAGCAATGGTGCTTGGCGGCCATGGAGATAGTATGGTTCCGATGCCCAGTTATACGAATGTGGCAGGTATTCCGATAACACAGCTGGTTCCCAAAGAGCGTATTGAAGCGCTCGTAGAAAGAACCAAACGTGGTGGTGCAGAGATAGTCGGGCTCCTGAAAACAGGCAGCGCTTATTACGCCCCGGCTGCCGCTGTTTCGCAGATGGTTGAAGCAATCGTGAAGGATAAAAATCGTGTGCTGCCTTGTGCAGCTTTCGTTGAGGGTGAATACGGCATTGACGGGCTTTATGCCGGTGTGCCAGTAAAATTAGGCCGTGGAGGCATTGAGGAAGTGATTGAGCTCCCTCTGAACGCTGAGGAACGGGCAGCGTTCGAAAAAAGTGCGAATGCAGTCAAAGCGCTCGTAGAGGCCATTAAAGCGGCCGCACTCGAGCACCACCACCACCACCACTGA | H20: MARKITVVGSGNVGATAAHWIAEKELGDVVLIDIVEGMPQGKALDLAQSLPVQGFDCKVVGTNDYKTTEDSDIVVITAGLARKPGMSRDDLLEKNQEIVKGVTEAVVKYSPQAIIIVVTNPLDAMVQVCYKSSGLPRERVIGMAGVLDSARFRTFLAMELGVSVEDVQAMVLGGHGDSMVPMPSYTNVAGIPITQLVPKERIEALVERTKRGGAEIVGLLKTGSAYYAPAAAVSQMVEAIVKDKNRVLPCAAFVEGEYGIDGLYAGVPVKLGRGGIEEVIELPLNAEERAAFEKSANAVKALVEAIKAAALEHHHHHH*
A21: 4806 | B21: ESM-MSA | C21: N | D21: N | E21: N | F21: N | G21: ATGTCTGTTCCGGCGAAACAAAAGAAAGCAATCAATGTGGCGGTTACGGGGGCGGCCGGTCAAATCTCCAATCATCTTTTGTTTATGCTGGCGTCAGGGGATGTTTTCGGCTTGGACCAGCCGATTACGCTGTATTTGCTGTTATCTGAACGCGCCCGGGAAGCCTTGGAGGGCGTAGCCATGGAGCTGGAAGACTCTTTGTGTCCCCTGTTACGCGAAGTTCATATCTCCATGGACCCACGCGAAGTATTTAAAAATTCCGATTGGGCTCTGTTAATCGGAGCCAAACCGCGAGGCCCTGGCATGGAAAGAGCAGACCTTCTGGAGGTTAATGGTCGTATTTATAAGGAACAGGGTCTGGCATTGAACGAAGTGGCTGCACGCGACGCCAAAGTCCTGGTTGTTGGCAACCCGTGCAATACGAACGCGTTGATTGGTTTAATGAACGCCCCGAATCTCCCACGGAAAAACATGCATGCACTGACAAGACTCGACGAAAATCGCGCTAAATCTCAACTGAGCTTGAAAGCGGGTAAGTTCTATACATCTATTACCAACATGACTATTTGGGGCAACCATTCGACCACTCAGGTACCAGATTTTGTAGATGCTACCATTGACGGTAAAAATGCTCGTGAAGTTATCCGCGATGATGATTGGCTGAAAAATGATTTCGTGCCTCTGGTCGCGAACAGAGGTGGAGTGCTGATTAAAAAATGGGGTCGTTCTTCAGCCGCATCTACCGCGGTATCGATCGCGGACCACCTGCACAGCCTTGTTACACCTACTAATCCGGGGGAGTATTTTAGTACGGCAGTGTATACTGATGGAAATCCCTATGGGATAGATGAGGGAATCGTATTTAGTATGCCATGTAAATCGAATGGTGAAGGTGATTACGAGATTATCGACGGCCTGATCATGGATGAGTGGTTGCAGGAGAAAATCCATGTGAGCGAAACGGAACTGATTCAAGAACGCGATGCTGTGGCACATTTAGTTCCGAAACCTGCCGTGGCCGCCGTCGTAGAAGCGGCCGCACTCGAGCACCACCACCACCACCACTGA | H21: MSVPAKQKKAINVAVTGAAGQISNHLLFMLASGDVFGLDQPITLYLLLSERAREALEGVAMELEDSLCPLLREVHISMDPREVFKNSDWALLIGAKPRGPGMERADLLEVNGRIYKEQGLALNEVAARDAKVLVVGNPCNTNALIGLMNAPNLPRKNMHALTRLDENRAKSQLSLKAGKFYTSITNMTIWGNHSTTQVPDFVDATIDGKNAREVIRDDDWLKNDFVPLVANRGGVLIKKWGRSSAASTAVSIADHLHSLVTPTNPGEYFSTAVYTDGNPYGIDEGIVFSMPCKSNGEGDYEIIDGLIMDEWLQEKIHVSETELIQERDAVAHLVPKPAVAAVVEAAALEHHHHHH*
A22: 40 | B22: ESM-MSA | C22: N | D22: Y | E22: N | F22: N | G22: ATGTCCGAAAATGCGCCCAAGCGGATCGCTGTAACGGGTGCCGCGGGCCAGATCGGCTATGCTTTATTATTTCGTATAGCCAAAGGTGAAGTCTATGGTCCGGACCAACCTGTAATTCTGCAGCTGCTGGATTTAGAACAGGCCCAACGTGCGGTCCAAGGGGTGGTTATGGAACTTGCTGATTGCGCCTTTCCGTTGCTGGCGGGGACGGTAGTAACAGATGACCCAGCGGTTGCTTTTGCCGACGTAGATGCGGCATTCCTGGTAGGTAGCAGACCTCGCACACCGGGCATGGAGCGCACTGATTTACTGCAGGTGAATGCGGGTATTTTCGTCACCCAGGGGCGCGCTCTCAATGAGGCGGCTAACAGAAAAGCCAAGGCTCTGGTAGTAGGGAATCCGGCAAACACAAACGCATTCATTACAGCTGCGAATGCTCCCGATATCCCGGCTGAAAACTTCACCTGTATGTTGCGCCTGGACCATAATAGAGCTTTGTGCCTGTTGGCAACCAAAGGTGGAGTAGGCGTACGTGAGATTAACAAGCTGGTCGTATGGGGGAACCATTCACCCACCATGTTCGCTGATTGGCGTGATGCCCAGATCAATGGACAGCCGTTACCTAAAGTGATTGGCGATGAAGAGTGGTTACGGGACGGCTTAATTCCGACAGTTAGCAAACGCGGGGCAGCGATTATTGCGGCTCGGGGCGCCAGCTCTGCTGCTTCGGCAGCTAATGCGGCCGTTGACCACGTTAGAGATTGGATTAATGGTTCGGAAGGGGATTGGGTTTCTATGGGTGTACCTAGCAACGGTGCTTATGATGTTCCGGAGGGCATCATGTTTGGGGTACCGGTGATCTCTGCTCGTGGTTCTTATGAGCGCGTAGAGGGCTTAGCTTTTACGGATTTTTCTCGCGAATACTCAGCTCGCACTGCCGCAGAATTAATTGGTGAACGAGAAGCAGTGCGGCCATTAATTGCGGCCGCACTCGAGCACCACCACCACCACCACTGA | H22: MSENAPKRIAVTGAAGQIGYALLFRIAKGEVYGPDQPVILQLLDLEQAQRAVQGVVMELADCAFPLLAGTVVTDDPAVAFADVDAAFLVGSRPRTPGMERTDLLQVNAGIFVTQGRALNEAANRKAKALVVGNPANTNAFITAANAPDIPAENFTCMLRLDHNRALCLLATKGGVGVREINKLVVWGNHSPTMFADWRDAQINGQPLPKVIGDEEWLRDGLIPTVSKRGAAIIAARGASSAASAANAAVDHVRDWINGSEGDWVSMGVPSNGAYDVPEGIMFGVPVISARGSYERVEGLAFTDFSREYSARTAAELIGEREAVRPLIAAALEHHHHHH*
A23: 2568 | B23: ESM-MSA | C23: N | D23: Y | E23: N | F23: N | G23: ATGTCTAGCAATCGTGTTAAGGTTGCGATTACGGGCGCCGCAGGTCAGATTGGCTATGCGCTTTTATTCAGAATTGCCTCAGGGCAAATGTTTGGTGCAGACACCCCGGTTGAACTGCAATTGCTGGAGGTAGAACCTGCGATTCCCGCTCTTAAGGGCGTCGTGATGGAGTTAGATGACTGCGCATTCCCTCTGTTGAACAACATGGTGCCTACAAACGACATTAATGACGGTTTTAAAGATGTGAATTGGGCTATATTGGTGGGGGCGGTGCCACGCAAAGTGGGTATGGAACGTCAAGATTTGCTGGAAATTAATGCTGGGATTTTTACTGAACAAGGTCGTGCAATTAATGATAATGCCGCTCATGATGTACGTACCCTCGTGATTGGGAATCCATGCAATACAAACTCGCTCATTGCTCAGCAGAATGCTCCTGACGTTCCAAAAGATCGTTTTTTCGCTATGACGCGCCTGGACGAGAATCGTGCCCGTACACAGATTGCTGCAAAAGCCGGTGTTGACGTCACCGCAGTCAGCAACATGACTATTTGGGGTAATCATTCAAGCACTCAATATCCCGATTTCTATAATGCTAAAATAAATGGCAAACCGGTTACAGAAGTGATTACTGACCAGGTTTGGCTGGAATCGGAATTTATCCCTGTGGTTCAGCAACGGGGCGCACAGATCATCGAAGCCAGAGGGGCATCGTCTGCAGCATCTGCCGCTAATGCAATTATTATGTCTATCTATAATCTTACACACGGAACCCCCGATGCCGATGGTTTTTCAGTTGCACACCCAAGTACCGGTGAGTACGATATAGATGAAGGGCTTATGTTCGGTTACCCTTGCCGATTCAAAGATGGTGAGTTAGAAGTTATCTCAGGGATTGAGCATAACGATTTTGCACAGGAAAAAGTTACTATGACACTGGAGGAATTAAAAGAAGAGCGGCAAGGTGTCAAAGAACTGGCGGCCGCACTCGAGCACCACCACCACCACCACTGA | H23: MSSNRVKVAITGAAGQIGYALLFRIASGQMFGADTPVELQLLEVEPAIPALKGVVMELDDCAFPLLNNMVPTNDINDGFKDVNWAILVGAVPRKVGMERQDLLEINAGIFTEQGRAINDNAAHDVRTLVIGNPCNTNSLIAQQNAPDVPKDRFFAMTRLDENRARTQIAAKAGVDVTAVSNMTIWGNHSSTQYPDFYNAKINGKPVTEVITDQVWLESEFIPVVQQRGAQIIEARGASSAASAANAIIMSIYNLTHGTPDADGFSVAHPSTGEYDIDEGLMFGYPCRFKDGELEVISGIEHNDFAQEKVTMTLEELKEERQGVKELAAALEHHHHHH*
A24: 317 | B24: ESM-MSA | C24: N | D24: Y | E24: N | F24: N | G24: ATGACACAGCCTGTCAGAGTGGCTGTTACAGGTGCGGCCGGCAACATTAGTTATAGCTTGCTGTTTCGCATTGCCGGGGGTGAAATGCTTGGCCCTGGTCAGCCTGTCGTCCTGCAGCTGCTTGAAATTAAGCCTGCCTTGGACGCATTGAAGGGCGTGGTCATGGAACTTGAGGATTGCGCCTTCCCGCTCCTTCAAGGTGTGAAGATCTCAGATGATCCGGCCGAAGCTTTTAAGGACGCAGAGGTTGCAATGTTAGTAGGCGCGCGTCCCCGCGGGCCCGGGATGGAACGGAAAGATCTTCTGACGGCAAATGGTGGAATCTTTCGAACCCAGGGCAAGGCGCTCAACGATAACGCAAGTGATTCTGTAAAAGTGTTAGTGGTGGGTAATCCTGCGAATACAAATGCCCTCATTGCGGCTACAAATGCACCCGATTTAAAACCGGGTAGATTTACCGCGATGACGCGGTTAGACCATAATCGTGCACTTGCACAGCTGGCGGAGAAAGCGGGTGTGAAAGTATCCCAGATCACCGGTATCACCATCTGGGGTAACCACTCTGTTACGCAGTATCCTGATCTGTCGAGAGCGACCGTGGCGGGCGAGGCGGCACTCAAAGTGATTGATGATAGCTGGTACAAGGAGACATTCATTCCGACAGTACAACAGCGTGGTGCCGCGATAATAAAGGCGCGTGGAATGAGTTCCGCAGCATCGGCTGCGTCAGCGGCGATTGAGCATATGCACGGTTGGTCACTTGGAACCGCAGAAGGCAATTGGATTTCAATGGCGGTTCCGTCCGACGGAAGCTACGGAGTTCCAGAAGGATTGATTTTCTCTTTTCCGTGTACAGTAAAGGATGGGGAATTCGAGATCGTTCAAGGATTACAAATAGACGAGTGGAGTCGCAATAAAATAGAGCTGACGACGCAGGAACTGATGGAAGAAAGAGATGGTGTCAATCATTTATTTGCGGCCGCACTCGAGCACCACCACCACCACCACTGA | H24: MTQPVRVAVTGAAGNISYSLLFRIAGGEMLGPGQPVVLQLLEIKPALDALKGVVMELEDCAFPLLQGVKISDDPAEAFKDAEVAMLVGARPRGPGMERKDLLTANGGIFRTQGKALNDNASDSVKVLVVGNPANTNALIAATNAPDLKPGRFTAMTRLDHNRALAQLAEKAGVKVSQITGITIWGNHSVTQYPDLSRATVAGEAALKVIDDSWYKETFIPTVQQRGAAIIKARGMSSAASAASAAIEHMHGWSLGTAEGNWISMAVPSDGSYGVPEGLIFSFPCTVKDGEFEIVQGLQIDEWSRNKIELTTQELMEERDGVNHLFAAALEHHHHHH*
A25: 2584 | B25: ESM-MSA | C25: N | D25: Y | E25: N | F25: N | G25: ATGGCCCGCTCTAAAATAGCATTAGTGGGGGGTGGCAATATCGGCGGAACTCTCGCACACTTGGCTGGCCTTAAAGAGCTGGGAGATATCGTAATATTCGATATTGTGAAAGGCCTGCCTGCCGGTAAAGCGCTGGACCTCGTTCAGGCCGCGCCGGTCCGCGGTTTTGATGCAAAAATCGAAGGTTCAAACTCTTATGAGGCTGTTAAGGGTGCCGACGTAGTTCTGGTAACAGCGGGTGTGGCACGGAAACCTGGGATGTCTCGCGATGACCTGTTGACTATCAATGCACAGACAATGGTTGACGTTGGTAAAGCTATAAAAAAGTACGCTCCGAATGCGTTTGTCCTGTGTATCACCAATCCCTTAGACGCCATGGTTTGGACCCTGCGAAACGTCACAGGACTGCCGTCGCAAAAGGTTTGTGGAATGGCTGGGGTGCTGGATTCGGCCCGCTTCCGCTATTTTCTTGCTCGTGAGCTGAAGGTCTCCGTAGAAGATATCACAGCCATGGTGCTTGGTGGCCATGGTGATACCATGGTGCCGCTGACACGTTACAGCACAGTTGCCGGTATACCTCTGCCTCACCTGGTTAAAATGGGCATGATTAGCCAGAATAAACTGGACGCGATTGTACAGCGAACCAGAAATGGTGGCGCCGAAATCGTTCAGCTTCTTAAAACTGGCTCTGCCTTTTACGCCCCTGCAGTGGCAGCAGTACAGATGGCTGAAGCTTATTTGAAAGACCGAAAACGTGTCTTGCCGTGCGCAGTAAAGTTGTCGGGCGAATATGGGGTCTCTAACATTTTTGTTGGCGTTCCCGTGATTCTGGGTGCGCGCGGAGTTGAGAAAGTTATCGAACTGAAATTATCTAAGGATGAAAAAAAAGCGTTTCTGAACAGCGTTCGAGCTGTCACAGGCTTGGTAAAAGAGTCAGATAAAGTGTTCGAAAGCGGCGCCGGGGCGGCGGCCGCACTCGAGCACCACCACCACCACCACTGA | H25: MARSKIALVGGGNIGGTLAHLAGLKELGDIVIFDIVKGLPAGKALDLVQAAPVRGFDAKIEGSNSYEAVKGADVVLVTAGVARKPGMSRDDLLTINAQTMVDVGKAIKKYAPNAFVLCITNPLDAMVWTLRNVTGLPSQKVCGMAGVLDSARFRYFLARELKVSVEDITAMVLGGHGDTMVPLTRYSTVAGIPLPHLVKMGMISQNKLDAIVQRTRNGGAEIVQLLKTGSAFYAPAVAAVQMAEAYLKDRKRVLPCAVKLSGEYGVSNIFVGVPVILGARGVEKVIELKLSKDEKKAFLNSVRAVTGLVKESDKVFESGAGAAAALEHHHHHH*
A26: 474 | B26: ESM-MSA | C26: N | D26: Y | E26: N | F26: N | G26: ATGAAAATAACCGTTGTCGGTGCAGGTGCCGTTGGAGCCACCTGCGCTGATAATATCGCTAGAAAGAAGCTTGTCGATGAGATCGTCTTGTTGGACATTAAAGAAGGCTTTGCAGAAGGAAAGGCCATCGATCTGATGCAGACCGCATCCCTCATGACTTTTGACACCAGAATCACCGGCGAAACAAATGATTACGCATTAACCAAAGGTTCTGATGTAATCATTATCACGAGCGGGATCCCTCGCAAACCCGGTATGACGCGTGAGGAACTTATAGGAGTGAATGCCCGCATTGTATCGAATGTGGCAAATAATTTACTCAAATATTCACCGAATGCTATAATCGTTGTGATCTCCAACCCGATGGACACCATGACGTACCTGACCTTTAAAGCAACTGGTCTGCCAAAAAATCAGATTATCGGAATGGGAGGAGTCCTGGACAGCTCCCGCTTTAAGTATCACATCTCTAAAGCCATGGATATATCTCCTAATGACATACATGGTGTAGTTCTGGGCGGACACGGTGATAGTACGATGATACCCCTGACGCGCTGCGCCACATATAACGGTGTCGAGATTAACAATTATCTTACAGATCAACAGTTAAAAACCGTGGCAGATGACACCATGACAGGAGGCGCAGCCTTGACTAGCCTCCTGGGTACGAGCGCTTGGTACGCCCCTGGCGCAGCTGGTGCACAGCTCGTAGAAGCCATTATCCGTGACGAAAAACGCCTGTTCCCATGCTGTGTATACTTGCATGGGGAGTATGGTCAAAAGGACATTTGCCTTGGGGTCCCGGTTATCATTGGGAAGAATGGCTGGGAGAAAATTTTGGACTATCCGCTCGACGCTGAAGAGCGCGCAAGTTTTGCCTCTTCTGCAGACGCAGTACGTAATATGAATAAGGTTCTCGTTACAGCGGCCGCACTCGAGCACCACCACCACCACCACTGA | H26: MKITVVGAGAVGATCADNIARKKLVDEIVLLDIKEGFAEGKAIDLMQTASLMTFDTRITGETNDYALTKGSDVIIITSGIPRKPGMTREELIGVNARIVSNVANNLLKYSPNAIIVVISNPMDTMTYLTFKATGLPKNQIIGMGGVLDSSRFKYHISKAMDISPNDIHGVVLGGHGDSTMIPLTRCATYNGVEINNYLTDQQLKTVADDTMTGGAALTSLLGTSAWYAPGAAGAQLVEAIIRDEKRLFPCCVYLHGEYGQKDICLGVPVIIGKNGWEKILDYPLDAEERASFASSADAVRNMNKVLVTAAALEHHHHHH*
A27: 2808 | B27: ESM-MSA | C27: N | D27: Y | E27: N | F27: N | G27: ATGGCAAGACCGAAAATCTCCATAGTGGGTGCAGGTCATGTTGGCGCCACCACCGCGTTCGAGGCGGCGCGCTTAGGTCTCGGCGACATAGTCCTGCTTGATATTCCGCCTGCAGATGGTATGCCTAAAGGTAAAGCACTTGACATGCAGGAGGCTGCCCCAATCGAAGGCTATGCGTCCGCGGTTGTGGGTACCAATTCTTATGAGGCAACAGAAGACAGCGATGTTGTAATAATCACGGCCGGCATGGCACGGAAACCGGGTATGAGTCGCGATGACCTTCTGGCCAAAAACGCGGGCATCGTCAAGGATGTTACCGAACAGGTTGCCAAGAAAAGTCCGAATGCAGTTTTAATCGTGATATCCAATCCGCTGGATGCGATGGTCTGGGTGGCTTATAAGGCCTCCGGTTTCCCTGTAAATCGTGTTGTGGGAATGGCCGGGGTATTAGACACCGCCCGCTATCGTACGTTCCTGGCTAGTGAGTTGGGAGTAAGTGTTGACGACGTTCATGCGATGCTGCTGGGGGGTCATGGGGACCCTATGGTTCCGTTAGTTCGGTACACTTCGGTTGGAGGTATTCCACTGCCTGATCTGATCAGTCAAGATAGACTGGATGCGATAGTCGAGCGGACACGCAGCGGTGGCGCTGAAATCGTTGGACTCCTGAAGACGGGTAGTGCGTTCTATGCACCATCAGCCTCAATGATCCAGATGGCTGAAGCGATACTGCGGGATCGCAAGCGTATACTGCCGTGTGCGGCGTATTGTAATCCTGAGTACGGAAATAATGGTTACTTTGTAGGTGTGCCGGTCAAGCTCGGTGCAAACGGCGTCGAGCAAATTGTGGAAGTTGCGCTGACCGCGGCCGCACTCGAGCACCACCACCACCACCACTGA | H27: MARPKISIVGAGHVGATTAFEAARLGLGDIVLLDIPPADGMPKGKALDMQEAAPIEGYASAVVGTNSYEATEDSDVVIITAGMARKPGMSRDDLLAKNAGIVKDVTEQVAKKSPNAVLIVISNPLDAMVWVAYKASGFPVNRVVGMAGVLDTARYRTFLASELGVSVDDVHAMLLGGHGDPMVPLVRYTSVGGIPLPDLISQDRLDAIVERTRSGGAEIVGLLKTGSAFYAPSASMIQMAEAILRDRKRILPCAAYCNPEYGNNGYFVGVPVKLGANGVEQIVEVALTAAALEHHHHHH*
A28: 692 | B28: ESM-MSA | C28: N | D28: N | E28: N | F28: N | G28: ATGCGGATCCCCGTGCGTATTGCTGTCACGGGAGCCGCGGGACAGATTTCATATGCTCTGCTTTTTCGTATTGCCAATGGCGACATGCTGGGCAAAGAGCATCCGATTATTTTACATCTCCTGGATATACCGCAGGCCCAACCCACGCTTCAAGGTGTTGCCATGGAACTGGAGGATTGTGCATTTCCGATGCTCCACCAGATCGTGATTACTGACGATCCTAAACGTGCATTCCATGATGCCGATCTCGTCCTGCTGGTGGGCTCGAAGCCGCGTTCAAAGGGTATGGAGAGATATGAACTGATCCGTGTTAACGCGGGCACCTTCGCAGACCAAGGTAAAGTATTAAATGATTTCGCGCAACATCACGTCAAAGTTCTTGTTATTGGGAACCCTGCAAACACCAATGCGATGATACTCATGCATAACGCACCGGATATCTCTTCGCGTAACTTCAGCAGTATGATGAGACTCGATCACAATCGTGCGATTAGCATGGTAGCAATGAAATTGTCTAGACCTATCACATCAGTTAAGAAGATGATCGTATGGGGCAACCACTCCTCAACTCAATACCCTGATTTATATCATGCAACGGTGGACGGTTCTAGCATTACAACAATTCTGCGCGATCATAAATGGGTAGAAAAGGAATTCATTCCCACTGTTCAGAAACGCGGCACCGCGGTTATTGAGGCCCGCAACCTCTCTTCAGCGGCGACGGCCGCTAATGCCGCAATCGGTCACATCCATGATTGGATCTTTGGAACTCACCATGATGATTGGGTGACAATGGCAGTTGTTTCTGATGGGTCTTATGGGGTTCCGCGCGGAATAGTCCATGGCTTTCCGGTTACTTGCCATCAAGGAGATTATAAAATTATAACCGATTTAACCATTTCTACCAATTCACGTCGCTATATGTTGGCTAATTATCACGAGCTTTTACAAGAGCGCGATCAGGTGGAACATTTACTTGCGGCCGCACTCGAGCACCACCACCACCACCACTGA | H28: MRIPVRIAVTGAAGQISYALLFRIANGDMLGKEHPIILHLLDIPQAQPTLQGVAMELEDCAFPMLHQIVITDDPKRAFHDADLVLLVGSKPRSKGMERYELIRVNAGTFADQGKVLNDFAQHHVKVLVIGNPANTNAMILMHNAPDISSRNFSSMMRLDHNRAISMVAMKLSRPITSVKKMIVWGNHSSTQYPDLYHATVDGSSITTILRDHKWVEKEFIPTVQKRGTAVIEARNLSSAATAANAAIGHIHDWIFGTHHDDWVTMAVVSDGSYGVPRGIVHGFPVTCHQGDYKIITDLTISTNSRRYMLANYHELLQERDQVEHLLAAALEHHHHHH*
A29: 3854 | B29: ESM-MSA | C29: N | D29: Y | E29: N | F29: N | G29: ATGGATCTCAGTAGCAGTAGCACCATGGGGAGAGCTAAAATAACTATTGTAGGCGCCGGCAACGTGGGTGCAACCACCGCACACTGGGCTGCTGCTGCAGAGCTGGGCAAAGACATAGTACTGCTGGATATACCGCAGACCGCCGGTATGCCGCAAGGCAAGGCGCTGGATATTATGCAAAGTACGCCTATTCTCGGTTTCGACAGCACAGTCATTGGAACTACCGATTACGCAGACACTAAAGGCTCCGACATTGTTGTAATCACAGCCGGAATTCCTCGTAAACCGGGTATGTCGAGAGATGACCTTCTGGCGACAAATAGTAAAATAATCCGGATGGTTTGTCAGCAAGTTCGCGACATCTCCCCTAACTGTGTGGTAATTGTTGTTTCCAATCCTCTCGACGCTATGGTGCACCTGACAAGTCGCGTTAGTGGGTTCCCGCGTAATCGGGTAATCGGGCAGGCGGGAGTTTTGGACACTGCAAGATATCGTACGTTTATTGCGCAAGAACTGGGGGTCAGTGTAGAAGATATTACCGCGTTGTTAATGGGTGGCCATGGGGATACAATGGTACCTATGCCGTCCTGCACCACAGTCGGCGGAATTCCAGTTACAAGACTCATTCCAAGAGATCGACTGGACGAGATCATGGACCGTGCGCGAAAAGGTGGCGCAGAAATTGTTAGCCTTCTGAAAACCGGTAGCGCTTATTATGCCCCATCCGCAGCTACCACCCAAATGATCGAGAGCATCATCGCAGATGAAAAAAAGTTATTGCCGTGCGCGGCATTTTGCCAAGCTGAGTACGGCGTTGGGGGTTTTTATGTGGGCGTTCCCGCCTTCCTGGGTAAAGGCGGTGTAGAAAAAATATTGGAACTCGAGTTAAATGAAGCCGAAAAGGCGGCATTCAATAAGTCTGTGGAAGGTGTTAAGGCTTTAGTTGCCGCAATGGCTAAGCTGCCGGCGGCCGCACTCGAGCACCACCACCACCACCACTGA | H29: MDLSSSSTMGRAKITIVGAGNVGATTAHWAAAAELGKDIVLLDIPQTAGMPQGKALDIMQSTPILGFDSTVIGTTDYADTKGSDIVVITAGIPRKPGMSRDDLLATNSKIIRMVCQQVRDISPNCVVIVVSNPLDAMVHLTSRVSGFPRNRVIGQAGVLDTARYRTFIAQELGVSVEDITALLMGGHGDTMVPMPSCTTVGGIPVTRLIPRDRLDEIMDRARKGGAEIVSLLKTGSAYYAPSAATTQMIESIIADEKKLLPCAAFCQAEYGVGGFYVGVPAFLGKGGVEKILELELNEAEKAAFNKSVEGVKALVAAMAKLPAAALEHHHHHH*
A30: 1047 | B30: ESM-MSA | C30: N | D30: Y | E30: N | F30: N | G30: ATGAACTTGCCGCCCGTCCGTGTTACGGTCACCGGTGCCGCCGGCCAGATTGGTTACTCCCTGCTCTTTCGCATTGCCTCTGGTCAGATGTTCGGTCCAGATGTTCCGGTACGTTTTCGCCTGCTCGAAATACCGACTGGAACGAAAGCAGCCGAAGGTACAGCAATGGAACTGGACGACTGTGTATTCCCGCTGCTGCTGGGCATGGAGGTGTTCGATGATCCGCGTGACGCCTTTAAGGGTACCAATGTTGCTCTGCTGGTTGGCTCGAGACCGCGTAAGCCGGGTATGGAGCGCAGCGATCTTATCGACGCGAATGGGGGCATATTTCGCCCGCAGGGAGCTGCCATTAACGAATTTGCCGCCGACGATGTTCGGGTACTGGTAGTTGGAAATCCAGCAAACACCAACGCGTTAATAGCGCAGAGTAATGCCCCGGACGTGCCACGTGAGCGGTTCAGTGCCATGACACGGCTGGATCACAACCGTGCCGTTGCTCAGTTAGCTGAGAGAGCTGGCGTACCCGTGTCCGATGTACGAGCACTTTGTATTTGGGGAAATCACTCGAGCACGCAGTTTCCTGACGTATTTCATGCAGAAATTGCAGGCCAGCCTAGTGCAGAAATAATTGAAGATGTCGATTGGTATTTGGACGAATTCATCCCTACCGTTGCCCAGCGGGGAGCAGCCATTATAGCTGCCCGCGGCGCTTCTAGCGCTGCCAGCGCAGCAAATGCCATTATAGACAGTGTACGAGACTGGGTGTTGGGGACCGACGAAGGGGACTGGGTTTCAGCGGGCGTCGCGTCCGATGGTTCCTATGACGTGCCAACCGGACTTATAGCCTCTTTCCCCGTGACTTCTTCCGATGGCACTTGGCAGATTGTCCAGGGAATGGAAATTACCGATTTTAGTAAAGAACGTATAGACGCAAGCGTTGCAGAGCTTATTGAGGAACGAGATGCTGTGGCTACGGCGGCCGCACTCGAGCACCACCACCACCACCACTGA | H30: MNLPPVRVTVTGAAGQIGYSLLFRIASGQMFGPDVPVRFRLLEIPTGTKAAEGTAMELDDCVFPLLLGMEVFDDPRDAFKGTNVALLVGSRPRKPGMERSDLIDANGGIFRPQGAAINEFAADDVRVLVVGNPANTNALIAQSNAPDVPRERFSAMTRLDHNRAVAQLAERAGVPVSDVRALCIWGNHSSTQFPDVFHAEIAGQPSAEIIEDVDWYLDEFIPTVAQRGAAIIAARGASSAASAANAIIDSVRDWVLGTDEGDWVSAGVASDGSYDVPTGLIASFPVTSSDGTWQIVQGMEITDFSKERIDASVAELIEERDAVATAAALEHHHHHH*
